Workbook

Sheet 材质
A1: 规范 | E1: [抗拉压弯ƒ, 抗剪ƒv, 端面承压ƒcc, 屈服强度ƒy, 抗拉强度ƒu](Mpa) | J1: E(N/mm2) | K1: G(N/mm2) | L1: α(1/[C]) | M1: ρ(Kg/m3) | Q1: 规范 | U1: fck(MPa) | V1: ftk(MPa) | W1: fc(MPa) | X1: ft(MPa) | Y1: Ec(N/mm2) | Z1: Gc(N/mm2) | AA1: α(1/[C]) | AE1: 规范 | AH1: fy(MPa) | AI1: f'y(MPa) | AJ1: fyk(MPa) | AK1: fstk(MPa) | AL1: E(N/mm2) | AM1: delta_gt(%)
A2: 钢结构规范名 | B2: 钢结构规范编号 | C2: Midas对应钢结构规范编号 | D2: 钢材牌号 | E2: 钢材厚度小于等于16mm | F2: 钢材厚度大于16mm小于等于40mm | G2: 钢材厚度大于40mm小于等于63mm | H2: 钢材厚度大于63mm小于等于80mm | I2: 钢材厚度大于80mm小于等于100mm | J2: 钢材弹性模量 | K2: 钢材剪切变形模量 | L2: 钢材线膨胀系数 | M2: 钢材质量密度 | N2: 钢材泊松比 | Q2: 混凝土规范名 | R2: 混凝土规范编号 | S2: Midas对应混凝土规范编号 | T2: 混凝土强度等级 | U2: 混凝土轴心抗压强度标准值 | V2: 混凝土轴心抗拉强度标准值 | W2: 混凝土轴心抗压强度设计值 | X2: 混凝土轴心抗拉强度设计值 | Y2: 混凝土弹性模量 | Z2: 混凝土剪切变形模量 | AA2: 混凝土线膨胀系数 | AB2: 混凝土泊松比 | AE2: 钢筋规范名 | AF2: 钢筋规范标号 | AG2: 钢筋牌号 | AH2: 钢筋抗拉强度设计值 | AI2: 钢筋抗压强度设计值 | AJ2: 钢筋屈服强度标准值 | AK2: 钢筋极限强度标准值 | AL2: 钢筋弹性模量 | AM2: 钢筋总伸长率限值
A3: 钢结构设计标准 | B3: GB 50017-2017 | C3: GB50017-17(S) | D3: Q235 | E3: 215,125,320,235,370 | F3: 205,120,320,225,370 | G3: 200,115,320,215,370 | H3: 200,115,320,215,370 | I3: 200,115,320,215,370 | J3: 206000 | K3: 79000 | L3: 0.00012 | M3: 7850 | N3: 0.3 | Q3: 混凝土结构设计标准 | R3: GB/T 50010-2010 | S3: TB10092-17(RC) | T3: C15 | U3: 10.0 | V3: 1.27 | W3: 7.2 | X3: 0.91 | Y3: 22000 | Z3: =Y3*0.4 -> 8800 | AA3: 0.00001 | AB3: 0.2 | AE3: 混凝土结构设计标准 | AF3: GB/T 50010-2010 | AG3: HPB300 | AH3: 270 | AI3: 270 | AJ3: 300 | AK3: 420 | AL3: 210000 | AM3: 10
A4: 钢结构设计标准 | B4: GB 50017-2017 | C4: GB50017-17(S) | D4: Q355 | E4: 305,175,400,345,470 | F4: 295,170,400,335,470 | G4: 290,165,400,325,470 | H4: 280,160,400,315,470 | I4: 270,155,400,305,470 | J4: 206000 | K4: 79000 | L4: 0.00012 | M4: 7850 | N4: 0.3 | Q4: 混凝土结构设计标准 | R4: GB/T 50010-2010 | S4: TB10092-17(RC) | T4: C20 | U4: 13.4 | V4: 1.54 | W4: 9.6 | X4: 1.10 | Y4: 25500 | Z4: =Y4*0.4 -> 10200 | AA4: 0.00001 | AB4: 0.2 | AE4: 混凝土结构设计标准 | AF4: GB/T 50010-2010 | AG4: HRB335 | AH4: 300 | AI4: 300 | AJ4: 335 | AK4: 455 | AL4: 200000 | AM4: 7.5
A5: 钢结构设计标准 | B5: GB 50017-2017 | C5: GB50017-17(S) | D5: Q390 | E5: 345,200,415,390,490 | F5: 330,190,415,370,490 | G5: 310,180,415,350,490 | H5: 295,170,415,330,490 | I5: 295,170,415,330,490 | J5: 206000 | K5: 79000 | L5: 0.00012 | M5: 7850 | N5: 0.3 | Q5: 混凝土结构设计标准 | R5: GB/T 50010-2010 | S5: TB10092-17(RC) | T5: C25 | U5: 16.7 | V5: 1.78 | W5: 11.9 | X5: 1.27 | Y5: 28000 | Z5: =Y5*0.4 -> 11200 | AA5: 0.00001 | AB5: 0.2 | AE5: 混凝土结构设计标准 | AF5: GB/T 50010-2010 | AG5: HRB400 | AH5: 360 | AI5: 360 | AJ5: 400 | AK5: 540 | AL5: 200000 | AM5: 7.5
A6: 钢结构设计标准 | B6: GB 50017-2017 | C6: GB50017-17(S) | D6: Q420 | E6: 375,215,440,420,520 | F6: 355,205,440,400,520 | G6: 320,185,440,380,520 | H6: 305,175,440,360,520 | I6: 305,175,440,360,520 | J6: 206000 | K6: 79000 | L6: 0.00012 | M6: 7850 | N6: 0.3 | Q6: 混凝土结构设计标准 | R6: GB/T 50010-2010 | S6: TB10092-17(RC) | T6: C30 | U6: 20.1 | V6: 2.01 | W6: 14.3 | X6: 1.43 | Y6: 30000 | Z6: =Y6*0.4 -> 12000 | AA6: 0.00001 | AB6: 0.2 | AE6: 混凝土结构设计标准 | AF6: GB/T 50010-2010 | AG6: HRBF400 | AH6: 360 | AI6: 360 | AJ6: 400 | AK6: 540 | AL6: 200000 | AM6: 7.5
A7: 钢结构设计标准 | B7: GB 50017-2017 | C7: GB50017-17(S) | D7: Q460 | E7: 410,235,470,460,550 | F7: 390,225,470,440,550 | G7: 355,205,470,420,550 | H7: 340,195,470,400,550 | I7: 340,195,470,400,550 | J7: 206000 | K7: 79000 | L7: 0.00012 | M7: 7850 | N7: 0.3 | Q7: 混凝土结构设计标准 | R7: GB/T 50010-2010 | S7: TB10092-17(RC) | T7: C35 | U7: 23.4 | V7: 2.20 | W7: 16.7 | X7: 1.57 | Y7: 31500 | Z7: =Y7*0.4 -> 12600 | AA7: 0.00001 | AB7: 0.2 | AE7: 混凝土结构设计标准 | AF7: GB/T 50010-2010 | AG7: RRB400 | AH7: 360 | AI7: 360 | AJ7: 400 | AK7: 540 | AL7: 200000 | AM7: 5
Q8: 混凝土结构设计标准 | R8: GB/T 50010-2010 | S8: TB10092-17(RC) | T8: C40 | U8: 26.8 | V8: 2.39 | W8: 19.1 | X8: 1.71 | Y8: 32500 | Z8: =Y8*0.4 -> 13000 | AA8: 0.00001 | AB8: 0.2 | AE8: 混凝土结构设计标准 | AF8: GB/T 50010-2010 | AG8: HRB500 | AH8: 435 | AI8: 435 | AJ8: 500 | AK8: 630 | AL8: 200000 | AM8: 7.5
Q9: 混凝土结构设计标准 | R9: GB/T 50010-2010 | S9: TB10092-17(RC) | T9: C45 | U9: 29.6 | V9: 2.51 | W9: 21.1 | X9: 1.80 | Y9: 33500 | Z9: =Y9*0.4 -> 13400 | AA9: 0.00001 | AB9: 0.2 | AE9: 混凝土结构设计标准 | AF9: GB/T 50010-2010 | AG9: HRBF500 | AH9: 435 | AI9: 435 | AJ9: 500 | AK9: 630 | AL9: 200000 | AM9: 7.5
Q10: 混凝土结构设计标准 | R10: GB/T 50010-2010 | S10: TB10092-17(RC) | T10: C50 | U10: 32.4 | V10: 2.64 | W10: 23.1 | X10: 1.89 | Y10: 34500 | Z10: =Y10*0.4 -> 13800 | AA10: 0.00001 | AB10: 0.2
Q11: 混凝土结构设计标准 | R11: GB/T 50010-2010 | S11: TB10092-17(RC) | T11: C55 | U11: 35.5 | V11: 2.74 | W11: 25.3 | X11: 1.96 | Y11: 35500 | Z11: =Y11*0.4 -> 14200 | AA11: 0.00001 | AB11: 0.2
Q12: 混凝土结构设计标准 | R12: GB/T 50010-2010 | S12: TB10092-17(RC) | T12: C60 | U12: 38.5 | V12: 2.85 | W12: 27.5 | X12: 2.04 | Y12: 36000 | Z12: =Y12*0.4 -> 14400 | AA12: 0.00001 | AB12: 0.2
Q13: 混凝土结构设计标准 | R13: GB/T 50010-2010 | S13: TB10092-17(RC) | T13: C65 | U13: 41.5 | V13: 2.93 | W13: 29.7 | X13: 2.09 | Y13: 36500 | Z13: =Y13*0.4 -> 14600 | AA13: 0.00001 | AB13: 0.2
Q14: 混凝土结构设计标准 | R14: GB/T 50010-2010 | S14: TB10092-17(RC) | T14: C70 | U14: 44.5 | V14: 2.99 | W14: 31.8 | X14: 2.14 | Y14: 37000 | Z14: =Y14*0.4 -> 14800 | AA14: 0.00001 | AB14: 0.2
Q15: 混凝土结构设计标准 | R15: GB/T 50010-2010 | S15: TB10092-17(RC) | T15: C75 | U15: 47.4 | V15: 3.05 | W15: 33.8 | X15: 2.18 | Y15: 37500 | Z15: =Y15*0.4 -> 15000 | AA15: 0.00001 | AB15: 0.2
Q16: 混凝土结构设计标准 | R16: GB/T 50010-2010 | S16: TB10092-17(RC) | T16: C80 | U16: 50.2 | V16: 3.11 | W16: 35.9 | X16: 2.22 | Y16: 38000 | Z16: =Y16*0.4 -> 15200 | AA16: 0.00001 | AB16: 0.2

Sheet I
A1: 型号 | B1: A | C1: Ix | D1: Iy | E1: Wx | F1: Wy | G1: ix | H1: iy | I1: 每延米重 | J1: H | K1: B | L1: tw | M1: tf1 | N1: r1 | O1: r2
A2: I10 | B2: 1433.3 | C2: 2450926.1 | D2: 327787.2 | E2: =ROUND(C2/J2*2,1) -> 49018.5 | F2: =ROUND(D2/K2*2,1) -> 9640.8 | G2: =ROUND((C2/B2)^0.5,1) -> 41.4 | H2: =ROUND((D2/B2)^0.5,1) -> 15.1 | I2: =ROUND(0.00785*B2,3) -> 11.251 | J2: 100 | K2: 68 | L2: 4.5 | M2: 7.6 | N2: 6.5 | O2: 3.3
A3: I12 | B3: 1780.4 | C3: 4359254.3 | D3: 469335.4 | E3: =ROUND(C3/J3*2,1) -> 72654.2 | F3: =ROUND(D3/K3*2,1) -> 12684.7 | G3: =ROUND((C3/B3)^0.5,1) -> 49.5 | H3: =ROUND((D3/B3)^0.5,1) -> 16.2 | I3: =ROUND(0.00785*B3,3) -> 13.976 | J3: 120 | K3: 74 | L3: 5 | M3: 8.4 | N3: 7 | O3: 3.5
A4: I12.6 | B4: 1810.4 | C4: 4879065.4 | D4: 469397.7 | E4: =ROUND(C4/J4*2,1) -> 77445.5 | F4: =ROUND(D4/K4*2,1) -> 12686.4 | G4: =ROUND((C4/B4)^0.5,1) -> 51.9 | H4: =ROUND((D4/B4)^0.5,1) -> 16.1 | I4: =ROUND(0.00785*B4,3) -> 14.212 | J4: 126 | K4: 74 | L4: 5 | M4: 8.4 | N4: 7 | O4: 3.5
A5: I14 | B5: 2150.1 | C5: 7115677.6 | D5: 643189.5 | E5: =ROUND(C5/J5*2,1) -> 101652.5 | F5: =ROUND(D5/K5*2,1) -> 16079.7 | G5: =ROUND((C5/B5)^0.5,1) -> 57.5 | H5: =ROUND((D5/B5)^0.5,1) -> 17.3 | I5: =ROUND(0.00785*B5,3) -> 16.878 | J5: 140 | K5: 80 | L5: 5.5 | M5: 9.1 | N5: 7.5 | O5: 3.8
A6: I16 | B6: 2611.3 | C6: 11269073 | D6: 930478.4 | E6: =ROUND(C6/J6*2,1) -> 140863.4 | F6: =ROUND(D6/K6*2,1) -> 21147.2 | G6: =ROUND((C6/B6)^0.5,1) -> 65.7 | H6: =ROUND((D6/B6)^0.5,1) -> 18.9 | I6: =ROUND(0.00785*B6,3) -> 20.499 | J6: 160 | K6: 88 | L6: 6 | M6: 9.9 | N6: 8 | O6: 4
A7: I18 | B7: 3073.5 | C7: 16688968 | D7: 1229299.7 | E7: =ROUND(C7/J7*2,1) -> 185433 | F7: =ROUND(D7/K7*2,1) -> 26155.3 | G7: =ROUND((C7/B7)^0.5,1) -> 73.7 | H7: =ROUND((D7/B7)^0.5,1) -> 20 | I7: =ROUND(0.00785*B7,3) -> 24.127 | J7: 180 | K7: 94 | L7: 6.5 | M7: 10.7 | N7: 8.5 | O7: 4.3
A8: I20a | B8: 3555.5 | C8: 23686558 | D8: 1579330.6 | E8: =ROUND(C8/J8*2,1) -> 236865.6 | F8: =ROUND(D8/K8*2,1) -> 31586.6 | G8: =ROUND((C8/B8)^0.5,1) -> 81.6 | H8: =ROUND((D8/B8)^0.5,1) -> 21.1 | I8: =ROUND(0.00785*B8,3) -> 27.911 | J8: 200 | K8: 100 | L8: 7 | M8: 11.4 | N8: 9 | O8: 4.5
A9: I20b | B9: 3955.5 | C9: 25019891 | D9: 1689523.6 | E9: =ROUND(C9/J9*2,1) -> 250198.9 | F9: =ROUND(D9/K9*2,1) -> 33127.9 | G9: =ROUND((C9/B9)^0.5,1) -> 79.5 | H9: =ROUND((D9/B9)^0.5,1) -> 20.7 | I9: =ROUND(0.00785*B9,3) -> 31.051 | J9: 200 | K9: 102 | L9: 9 | M9: 11.4 | N9: 9 | O9: 4.5
A10: I22a | B10: 4210.3 | C10: 34059321 | D10: 2258776.1 | E10: =ROUND(C10/J10*2,1) -> 309630.2 | F10: =ROUND(D10/K10*2,1) -> 41068.7 | G10: =ROUND((C10/B10)^0.5,1) -> 89.9 | H10: =ROUND((D10/B10)^0.5,1) -> 23.2 | I10: =ROUND(0.00785*B10,3) -> 33.051 | J10: 220 | K10: 110 | L10: 7.5 | M10: 12.3 | N10: 9.5 | O10: 4.8
A11: I22b | B11: 4650.3 | C11: 35833987 | D11: 2401633.6 | E11: =ROUND(C11/J11*2,1) -> 325763.5 | F11: =ROUND(D11/K11*2,1) -> 42886.3 | G11: =ROUND((C11/B11)^0.5,1) -> 87.8 | H11: =ROUND((D11/B11)^0.5,1) -> 22.7 | I11: =ROUND(0.00785*B11,3) -> 36.505 | J11: 220 | K11: 112 | L11: 9.5 | M11: 12.3 | N11: 9.5 | O11: 4.8
A12: I25a | B12: 4851.9 | C12: 50181160 | D12: 2804979.7 | E12: =ROUND(C12/J12*2,1) -> 401449.3 | F12: =ROUND(D12/K12*2,1) -> 48361.7 | G12: =ROUND((C12/B12)^0.5,1) -> 101.7 | H12: =ROUND((D12/B12)^0.5,1) -> 24 | I12: =ROUND(0.00785*B12,3) -> 38.087 | J12: 250 | K12: 116 | L12: 8 | M12: 13 | N12: 10 | O12: 5
A13: I25b | B13: 5351.9 | C13: 52785327 | D13: 2973664 | E13: =ROUND(C13/J13*2,1) -> 422282.6 | F13: =ROUND(D13/K13*2,1) -> 50401.1 | G13: =ROUND((C13/B13)^0.5,1) -> 99.3 | H13: =ROUND((D13/B13)^0.5,1) -> 23.6 | I13: =ROUND(0.00785*B13,3) -> 42.012 | J13: 250 | K13: 118 | L13: 10 | M13: 13 | N13: 10 | O13: 5
... A36: I63c | B36: 17978.5 | C36: 1023314100 | D36: 18420783 | E36: =ROUND(C36/J36*2,1) -> 3248616.2 | F36: =ROUND(D36/K36*2,1) -> 204675.4 | G36: =ROUND((C36/B36)^0.5,1) -> 238.6 | H36: =ROUND((D36/B36)^0.5,1) -> 32 | I36: =ROUND(0.00785*B36,3) -> 141.131 | J36: 630 | K36: 180 | L36: 17 | M36: 22 | N36: 15 | O36: 7.5

Sheet 2I
A1: 型号 | B1: A | C1: Ix | D1: Iy | E1: Wx | F1: Wy | G1: ix | H1: iy | I1: 每延米重 | J1: H | K1: B | L1: tw | M1: tf1 | N1: C | O1: tf2
A2: ="2"&I!A2 -> 2I10 | B2: =2*I!B2 -> 2866.6 | C2: =2*I!C2 -> 4901852.2 | D2: =ROUND(2*I!D2+I!B2*I!K2^2/2,1) -> 3969364 | E2: =ROUND(C2/J2*2,1) -> 98037 | F2: =ROUND(D2/K2*2,1) -> 58373 | G2: =ROUND((C2/B2)^0.5,1) -> 41.4 | H2: =ROUND((D2/B2)^0.5,1) -> 37.2 | I2: =ROUND(0.00785*B2,3) -> 22.503 | J2: =I!J2 -> 100 | K2: =2*I!K2 -> 136 | L2: =I!L2 -> 4.5 | M2: =I!M2 -> 7.6 | N2: =I!K2 -> 68 | O2: =M2 -> 7.6
A3: ="2"&I!A3 -> 2I12 | B3: =2*I!B3 -> 3560.8 | C3: =2*I!C3 -> 8718508.6 | D3: =ROUND(2*I!D3+I!B3*I!K3^2/2,1) -> 5813406 | E3: =ROUND(C3/J3*2,1) -> 145308.5 | F3: =ROUND(D3/K3*2,1) -> 78559.5 | G3: =ROUND((C3/B3)^0.5,1) -> 49.5 | H3: =ROUND((D3/B3)^0.5,1) -> 40.4 | I3: =ROUND(0.00785*B3,3) -> 27.952 | J3: =I!J3 -> 120 | K3: =2*I!K3 -> 148 | L3: =I!L3 -> 5 | M3: =I!M3 -> 8.4 | N3: =I!K3 -> 74 | O3: =M3 -> 8.4
A4: ="2"&I!A4 -> 2I12.6 | B4: =2*I!B4 -> 3620.8 | C4: =2*I!C4 -> 9758130.8 | D4: =ROUND(2*I!D4+I!B4*I!K4^2/2,1) -> 5895670.6 | E4: =ROUND(C4/J4*2,1) -> 154891 | F4: =ROUND(D4/K4*2,1) -> 79671.2 | G4: =ROUND((C4/B4)^0.5,1) -> 51.9 | H4: =ROUND((D4/B4)^0.5,1) -> 40.4 | I4: =ROUND(0.00785*B4,3) -> 28.423 | J4: =I!J4 -> 126 | K4: =2*I!K4 -> 148 | L4: =I!L4 -> 5 | M4: =I!M4 -> 8.4 | N4: =I!K4 -> 74 | O4: =M4 -> 8.4
A5: ="2"&I!A5 -> 2I14 | B5: =2*I!B5 -> 4300.2 | C5: =2*I!C5 -> 14231355 | D5: =ROUND(2*I!D5+I!B5*I!K5^2/2,1) -> 8166699 | E5: =ROUND(C5/J5*2,1) -> 203305.1 | F5: =ROUND(D5/K5*2,1) -> 102083.7 | G5: =ROUND((C5/B5)^0.5,1) -> 57.5 | H5: =ROUND((D5/B5)^0.5,1) -> 43.6 | I5: =ROUND(0.00785*B5,3) -> 33.757 | J5: =I!J5 -> 140 | K5: =2*I!K5 -> 160 | L5: =I!L5 -> 5.5 | M5: =I!M5 -> 9.1 | N5: =I!K5 -> 80 | O5: =M5 -> 9.1
A6: ="2"&I!A6 -> 2I16 | B6: =2*I!B6 -> 5222.6 | C6: =2*I!C6 -> 22538146 | D6: =ROUND(2*I!D6+I!B6*I!K6^2/2,1) -> 11971910 | E6: =ROUND(C6/J6*2,1) -> 281726.8 | F6: =ROUND(D6/K6*2,1) -> 136044.4 | G6: =ROUND((C6/B6)^0.5,1) -> 65.7 | H6: =ROUND((D6/B6)^0.5,1) -> 47.9 | I6: =ROUND(0.00785*B6,3) -> 40.997 | J6: =I!J6 -> 160 | K6: =2*I!K6 -> 176 | L6: =I!L6 -> 6 | M6: =I!M6 -> 9.9 | N6: =I!K6 -> 88 | O6: =M6 -> 9.9
A7: ="2"&I!A7 -> 2I18 | B7: =2*I!B7 -> 6147 | C7: =2*I!C7 -> 33377936 | D7: =ROUND(2*I!D7+I!B7*I!K7^2/2,1) -> 16037322 | E7: =ROUND(C7/J7*2,1) -> 370866 | F7: =ROUND(D7/K7*2,1) -> 170609.8 | G7: =ROUND((C7/B7)^0.5,1) -> 73.7 | H7: =ROUND((D7/B7)^0.5,1) -> 51.1 | I7: =ROUND(0.00785*B7,3) -> 48.254 | J7: =I!J7 -> 180 | K7: =2*I!K7 -> 188 | L7: =I!L7 -> 6.5 | M7: =I!M7 -> 10.7 | N7: =I!K7 -> 94 | O7: =M7 -> 10.7
A8: ="2"&I!A8 -> 2I20a | B8: =2*I!B8 -> 7111 | C8: =2*I!C8 -> 47373116 | D8: =ROUND(2*I!D8+I!B8*I!K8^2/2,1) -> 20936161 | E8: =ROUND(C8/J8*2,1) -> 473731.2 | F8: =ROUND(D8/K8*2,1) -> 209361.6 | G8: =ROUND((C8/B8)^0.5,1) -> 81.6 | H8: =ROUND((D8/B8)^0.5,1) -> 54.3 | I8: =ROUND(0.00785*B8,3) -> 55.821 | J8: =I!J8 -> 200 | K8: =2*I!K8 -> 200 | L8: =I!L8 -> 7 | M8: =I!M8 -> 11.4 | N8: =I!K8 -> 100 | O8: =M8 -> 11.4
A9: ="2"&I!A9 -> 2I20b | B9: =2*I!B9 -> 7911 | C9: =2*I!C9 -> 50039782 | D9: =ROUND(2*I!D9+I!B9*I!K9^2/2,1) -> 23955558 | E9: =ROUND(C9/J9*2,1) -> 500397.8 | F9: =ROUND(D9/K9*2,1) -> 234858.4 | G9: =ROUND((C9/B9)^0.5,1) -> 79.5 | H9: =ROUND((D9/B9)^0.5,1) -> 55 | I9: =ROUND(0.00785*B9,3) -> 62.101 | J9: =I!J9 -> 200 | K9: =2*I!K9 -> 204 | L9: =I!L9 -> 9 | M9: =I!M9 -> 11.4 | N9: =I!K9 -> 102 | O9: =M9 -> 11.4
A10: ="2"&I!A10 -> 2I22a | B10: =2*I!B10 -> 8420.6 | C10: =2*I!C10 -> 68118642 | D10: =ROUND(2*I!D10+I!B10*I!K10^2/2,1) -> 29989867 | E10: =ROUND(C10/J10*2,1) -> 619260.4 | F10: =ROUND(D10/K10*2,1) -> 272635.2 | G10: =ROUND((C10/B10)^0.5,1) -> 89.9 | H10: =ROUND((D10/B10)^0.5,1) -> 59.7 | I10: =ROUND(0.00785*B10,3) -> 66.102 | J10: =I!J10 -> 220 | K10: =2*I!K10 -> 220 | L10: =I!L10 -> 7.5 | M10: =I!M10 -> 12.3 | N10: =I!K10 -> 110 | O10: =M10 -> 12.3
A11: ="2"&I!A11 -> 2I22b | B11: =2*I!B11 -> 9300.6 | C11: =2*I!C11 -> 71667974 | D11: =ROUND(2*I!D11+I!B11*I!K11^2/2,1) -> 33969949 | E11: =ROUND(C11/J11*2,1) -> 651527 | F11: =ROUND(D11/K11*2,1) -> 303303.1 | G11: =ROUND((C11/B11)^0.5,1) -> 87.8 | H11: =ROUND((D11/B11)^0.5,1) -> 60.4 | I11: =ROUND(0.00785*B11,3) -> 73.01 | J11: =I!J11 -> 220 | K11: =2*I!K11 -> 224 | L11: =I!L11 -> 9.5 | M11: =I!M11 -> 12.3 | N11: =I!K11 -> 112 | O11: =M11 -> 12.3
A12: ="2"&I!A12 -> 2I25a | B12: =2*I!B12 -> 9703.8 | C12: =2*I!C12 -> 100362320 | D12: =ROUND(2*I!D12+I!B12*I!K12^2/2,1) -> 38253543 | E12: =ROUND(C12/J12*2,1) -> 802898.6 | F12: =ROUND(D12/K12*2,1) -> 329771.9 | G12: =ROUND((C12/B12)^0.5,1) -> 101.7 | H12: =ROUND((D12/B12)^0.5,1) -> 62.8 | I12: =ROUND(0.00785*B12,3) -> 76.175 | J12: =I!J12 -> 250 | K12: =2*I!K12 -> 232 | L12: =I!L12 -> 8 | M12: =I!M12 -> 13 | N12: =I!K12 -> 116 | O12: =M12 -> 13
A13: ="2"&I!A13 -> 2I25b | B13: =2*I!B13 -> 10703.8 | C13: =2*I!C13 -> 105570654 | D13: =ROUND(2*I!D13+I!B13*I!K13^2/2,1) -> 43207256 | E13: =ROUND(C13/J13*2,1) -> 844565.2 | F13: =ROUND(D13/K13*2,1) -> 366163.2 | G13: =ROUND((C13/B13)^0.5,1) -> 99.3 | H13: =ROUND((D13/B13)^0.5,1) -> 63.5 | I13: =ROUND(0.00785*B13,3) -> 84.025 | J13: =I!J13 -> 250 | K13: =2*I!K13 -> 236 | L13: =I!L13 -> 10 | M13: =I!M13 -> 13 | N13: =I!K13 -> 118 | O13: =M13 -> 13
... A36: ="2"&I!A36 -> 2I63c | B36: =2*I!B36 -> 35957 | C36: =2*I!C36 -> 2046628200 | D36: =ROUND(2*I!D36+I!B36*I!K36^2/2,1) -> 328093266 | E36: =ROUND(C36/J36*2,1) -> 6497232.4 | F36: =ROUND(D36/K36*2,1) -> 1822740.4 | G36: =ROUND((C36/B36)^0.5,1) -> 238.6 | H36: =ROUND((D36/B36)^0.5,1) -> 95.5 | I36: =ROUND(0.00785*B36,3) -> 282.262 | J36: =I!J36 -> 630 | K36: =2*I!K36 -> 360 | L36: =I!L36 -> 17 | M36: =I!M36 -> 22 | N36: =I!K36 -> 180 | O36: =M36 -> 22

Sheet HM
A1: 型号 | B1: A | C1: Ix | D1: Iy | E1: Wx | F1: Wy | G1: ix | H1: iy | I1: 每延米重 | J1: H | K1: B | L1: tw | M1: tf1 | N1: r1
A2: HM148X100 | B2: 2640.6 | C2: 10046379 | D2: 1503968.9 | E2: =ROUND(C2/J2*2,1) -> 135761.9 | F2: =ROUND(D2/K2*2,1) -> 30079.4 | G2: =ROUND((C2/B2)^0.5,1) -> 61.7 | H2: =ROUND((D2/B2)^0.5,1) -> 23.9 | I2: =ROUND(0.00785*B2,3) -> 20.729 | J2: 148 | K2: 100 | L2: 6 | M2: 9 | N2: 8
A3: HM194X150 | B3: 3816.6 | C3: 26295089 | D3: 5067296.9 | E3: =ROUND(C3/J3*2,1) -> 271083.4 | F3: =ROUND(D3/K3*2,1) -> 67564 | G3: =ROUND((C3/B3)^0.5,1) -> 83 | H3: =ROUND((D3/B3)^0.5,1) -> 36.4 | I3: =ROUND(0.00785*B3,3) -> 29.96 | J3: 194 | K3: 150 | L3: 6 | M3: 9 | N3: 8
A4: HM244X175 | B4: 5563.9 | C4: 60537570 | D4: 9840020.9 | E4: =ROUND(C4/J4*2,1) -> 496209.6 | F4: =ROUND(D4/K4*2,1) -> 112457.4 | G4: =ROUND((C4/B4)^0.5,1) -> 104.3 | H4: =ROUND((D4/B4)^0.5,1) -> 42.1 | I4: =ROUND(0.00785*B4,3) -> 43.677 | J4: 244 | K4: 175 | L4: 7 | M4: 11 | N4: 13
A5: HM294X200 | B5: 7119.9 | C5: 111392170 | D5: 16020769 | E5: =ROUND(C5/J5*2,1) -> 757769.9 | F5: =ROUND(D5/K5*2,1) -> 160207.7 | G5: =ROUND((C5/B5)^0.5,1) -> 125.1 | H5: =ROUND((D5/B5)^0.5,1) -> 47.4 | I5: =ROUND(0.00785*B5,3) -> 55.891 | J5: 294 | K5: 200 | L5: 8 | M5: 12 | N5: 13
A6: HM298X201 | B6: 8217.9 | C6: 131120940 | D6: 18974896 | E6: =ROUND(C6/J6*2,1) -> 880006.3 | F6: =ROUND(D6/K6*2,1) -> 188804.9 | G6: =ROUND((C6/B6)^0.5,1) -> 126.3 | H6: =ROUND((D6/B6)^0.5,1) -> 48.1 | I6: =ROUND(0.00785*B6,3) -> 64.511 | J6: 298 | K6: 201 | L6: 9 | M6: 14 | N6: 13
A7: HM340X250 | B7: 9967.9 | C7: 212616150 | D7: 36487712 | E7: =ROUND(C7/J7*2,1) -> 1250683.2 | F7: =ROUND(D7/K7*2,1) -> 291901.7 | G7: =ROUND((C7/B7)^0.5,1) -> 146 | H7: =ROUND((D7/B7)^0.5,1) -> 60.5 | I7: =ROUND(0.00785*B7,3) -> 78.248 | J7: 340 | K7: 250 | L7: 9 | M7: 14 | N7: 13
A8: HM390X300 | B8: 13339.9 | C8: 379092600 | D8: 72041513 | E8: =ROUND(C8/J8*2,1) -> 1944064.6 | F8: =ROUND(D8/K8*2,1) -> 480276.8 | G8: =ROUND((C8/B8)^0.5,1) -> 168.6 | H8: =ROUND((D8/B8)^0.5,1) -> 73.5 | I8: =ROUND(0.00785*B8,3) -> 104.718 | J8: 390 | K8: 300 | L8: 10 | M8: 16 | N8: 13
A9: HM440X300 | B9: 15403.9 | C9: 547891230 | D9: 81057824 | E9: =ROUND(C9/J9*2,1) -> 2490414.7 | F9: =ROUND(D9/K9*2,1) -> 540385.5 | G9: =ROUND((C9/B9)^0.5,1) -> 188.6 | H9: =ROUND((D9/B9)^0.5,1) -> 72.5 | I9: =ROUND(0.00785*B9,3) -> 120.921 | J9: 440 | K9: 300 | L9: 11 | M9: 18 | N9: 13
A10: HM482X300 | B10: 14131.9 | C10: 583466510 | D10: 67563148 | E10: =ROUND(C10/J10*2,1) -> 2421022.9 | F10: =ROUND(D10/K10*2,1) -> 450421 | G10: =ROUND((C10/B10)^0.5,1) -> 203.2 | H10: =ROUND((D10/B10)^0.5,1) -> 69.1 | I10: =ROUND(0.00785*B10,3) -> 110.935 | J10: 482 | K10: 300 | L10: 11 | M10: 15 | N10: 13
A11: HM488X300 | B11: 15931.9 | C11: 689319110 | D11: 81063148 | E11: =ROUND(C11/J11*2,1) -> 2825078.3 | F11: =ROUND(D11/K11*2,1) -> 540421 | G11: =ROUND((C11/B11)^0.5,1) -> 208 | H11: =ROUND((D11/B11)^0.5,1) -> 71.3 | I11: =ROUND(0.00785*B11,3) -> 125.065 | J11: 488 | K11: 300 | L11: 11 | M11: 18 | N11: 13
A12: HM544X300 | B12: 14813.9 | C12: 764602850 | D12: 67570025 | E12: =ROUND(C12/J12*2,1) -> 2811039.9 | F12: =ROUND(D12/K12*2,1) -> 450466.8 | G12: =ROUND((C12/B12)^0.5,1) -> 227.2 | H12: =ROUND((D12/B12)^0.5,1) -> 67.5 | I12: =ROUND(0.00785*B12,3) -> 116.289 | J12: 544 | K12: 300 | L12: 11 | M12: 15 | N12: 13
A13: HM550X300 | B13: 16613.9 | C13: 899248250 | D13: 81070025 | E13: =ROUND(C13/J13*2,1) -> 3269993.6 | F13: =ROUND(D13/K13*2,1) -> 540466.8 | G13: =ROUND((C13/B13)^0.5,1) -> 232.7 | H13: =ROUND((D13/B13)^0.5,1) -> 69.9 | I13: =ROUND(0.00785*B13,3) -> 130.419 | J13: 550 | K13: 300 | L13: 11 | M13: 18 | N13: 13
... A16: HM594X302 | B16: 21723.9 | C16: 1336685500 | D16: 105726640 | E16: =ROUND(C16/J16*2,1) -> 4500624.6 | F16: =ROUND(D16/K16*2,1) -> 700176.4 | G16: =ROUND((C16/B16)^0.5,1) -> 248.1 | H16: =ROUND((D16/B16)^0.5,1) -> 69.8 | I16: =ROUND(0.00785*B16,3) -> 170.533 | J16: 594 | K16: 302 | L16: 14 | M16: 23 | N16: 13

Sheet 2HM
A1: 型号 | B1: A | C1: Ix | D1: Iy | E1: Wx | F1: Wy | G1: ix | H1: iy | I1: 每延米重 | J1: H | K1: B | L1: tw | M1: tf1 | N1: C | O1: tf2
A2: ="2"&HM!A2 -> 2HM148X100 | B2: =2*HM!B2 -> 5281.2 | C2: =2*HM!C2 -> 20092758 | D2: =ROUND(2*HM!D2+HM!B2*HM!K2^2/2,2) -> 16210938 | E2: =ROUND(C2/J2*2,1) -> 271523.8 | F2: =ROUND(D2/K2*2,1) -> 162109.4 | G2: =ROUND((C2/B2)^0.5,1) -> 61.7 | H2: =ROUND((D2/B2)^0.5,1) -> 55.4 | I2: =ROUND(0.00785*B2,3) -> 41.457 | J2: =HM!J2 -> 148 | K2: =2*HM!K2 -> 200 | L2: =HM!L2 -> 6 | M2: =HM!M2 -> 9 | N2: =HM!K2 -> 100 | O2: =M2 -> 9
A3: ="2"&HM!A3 -> 2HM194X150 | B3: =2*HM!B3 -> 7633.2 | C3: =2*HM!C3 -> 52590178 | D3: =ROUND(2*HM!D3+HM!B3*HM!K3^2/2,2) -> 53071344 | E3: =ROUND(C3/J3*2,1) -> 542166.8 | F3: =ROUND(D3/K3*2,1) -> 353809 | G3: =ROUND((C3/B3)^0.5,1) -> 83 | H3: =ROUND((D3/B3)^0.5,1) -> 83.4 | I3: =ROUND(0.00785*B3,3) -> 59.921 | J3: =HM!J3 -> 194 | K3: =2*HM!K3 -> 300 | L3: =HM!L3 -> 6 | M3: =HM!M3 -> 9 | N3: =HM!K3 -> 150 | O3: =M3 -> 9
A4: ="2"&HM!A4 -> 2HM244X175 | B4: =2*HM!B4 -> 11127.8 | C4: =2*HM!C4 -> 121075140 | D4: =ROUND(2*HM!D4+HM!B4*HM!K4^2/2,2) -> 1.0487726e+08 | E4: =ROUND(C4/J4*2,1) -> 992419.2 | F4: =ROUND(D4/K4*2,1) -> 599298.6 | G4: =ROUND((C4/B4)^0.5,1) -> 104.3 | H4: =ROUND((D4/B4)^0.5,1) -> 97.1 | I4: =ROUND(0.00785*B4,3) -> 87.353 | J4: =HM!J4 -> 244 | K4: =2*HM!K4 -> 350 | L4: =HM!L4 -> 7 | M4: =HM!M4 -> 11 | N4: =HM!K4 -> 175 | O4: =M4 -> 11
A5: ="2"&HM!A5 -> 2HM294X200 | B5: =2*HM!B5 -> 14239.8 | C5: =2*HM!C5 -> 222784340 | D5: =ROUND(2*HM!D5+HM!B5*HM!K5^2/2,2) -> 174439538 | E5: =ROUND(C5/J5*2,1) -> 1515539.7 | F5: =ROUND(D5/K5*2,1) -> 872197.7 | G5: =ROUND((C5/B5)^0.5,1) -> 125.1 | H5: =ROUND((D5/B5)^0.5,1) -> 110.7 | I5: =ROUND(0.00785*B5,3) -> 111.782 | J5: =HM!J5 -> 294 | K5: =2*HM!K5 -> 400 | L5: =HM!L5 -> 8 | M5: =HM!M5 -> 12 | N5: =HM!K5 -> 200 | O5: =M5 -> 12
A6: ="2"&HM!A6 -> 2HM298X201 | B6: =2*HM!B6 -> 16435.8 | C6: =2*HM!C6 -> 262241880 | D6: =ROUND(2*HM!D6+HM!B6*HM!K6^2/2,2) -> 2.0395548e+08 | E6: =ROUND(C6/J6*2,1) -> 1760012.6 | F6: =ROUND(D6/K6*2,1) -> 1014703.9 | G6: =ROUND((C6/B6)^0.5,1) -> 126.3 | H6: =ROUND((D6/B6)^0.5,1) -> 111.4 | I6: =ROUND(0.00785*B6,3) -> 129.021 | J6: =HM!J6 -> 298 | K6: =2*HM!K6 -> 402 | L6: =HM!L6 -> 9 | M6: =HM!M6 -> 14 | N6: =HM!K6 -> 201 | O6: =M6 -> 14
A7: ="2"&HM!A7 -> 2HM340X250 | B7: =2*HM!B7 -> 19935.8 | C7: =2*HM!C7 -> 425232300 | D7: =ROUND(2*HM!D7+HM!B7*HM!K7^2/2,2) -> 384472299 | E7: =ROUND(C7/J7*2,1) -> 2501366.5 | F7: =ROUND(D7/K7*2,1) -> 1537889.2 | G7: =ROUND((C7/B7)^0.5,1) -> 146 | H7: =ROUND((D7/B7)^0.5,1) -> 138.9 | I7: =ROUND(0.00785*B7,3) -> 156.496 | J7: =HM!J7 -> 340 | K7: =2*HM!K7 -> 500 | L7: =HM!L7 -> 9 | M7: =HM!M7 -> 14 | N7: =HM!K7 -> 250 | O7: =M7 -> 14
A8: ="2"&HM!A8 -> 2HM390X300 | B8: =2*HM!B8 -> 26679.8 | C8: =2*HM!C8 -> 758185200 | D8: =ROUND(2*HM!D8+HM!B8*HM!K8^2/2,2) -> 744378526 | E8: =ROUND(C8/J8*2,1) -> 3888129.2 | F8: =ROUND(D8/K8*2,1) -> 2481261.8 | G8: =ROUND((C8/B8)^0.5,1) -> 168.6 | H8: =ROUND((D8/B8)^0.5,1) -> 167 | I8: =ROUND(0.00785*B8,3) -> 209.436 | J8: =HM!J8 -> 390 | K8: =2*HM!K8 -> 600 | L8: =HM!L8 -> 10 | M8: =HM!M8 -> 16 | N8: =HM!K8 -> 300 | O8: =M8 -> 16
A9: ="2"&HM!A9 -> 2HM440X300 | B9: =2*HM!B9 -> 30807.8 | C9: =2*HM!C9 -> 1095782460 | D9: =ROUND(2*HM!D9+HM!B9*HM!K9^2/2,2) -> 855291148 | E9: =ROUND(C9/J9*2,1) -> 4980829.4 | F9: =ROUND(D9/K9*2,1) -> 2850970.5 | G9: =ROUND((C9/B9)^0.5,1) -> 188.6 | H9: =ROUND((D9/B9)^0.5,1) -> 166.6 | I9: =ROUND(0.00785*B9,3) -> 241.841 | J9: =HM!J9 -> 440 | K9: =2*HM!K9 -> 600 | L9: =HM!L9 -> 11 | M9: =HM!M9 -> 18 | N9: =HM!K9 -> 300 | O9: =M9 -> 18
A10: ="2"&HM!A10 -> 2HM482X300 | B10: =2*HM!B10 -> 28263.8 | C10: =2*HM!C10 -> 1166933020 | D10: =ROUND(2*HM!D10+HM!B10*HM!K10^2/2,2) -> 771061796 | E10: =ROUND(C10/J10*2,1) -> 4842045.7 | F10: =ROUND(D10/K10*2,1) -> 2570206 | G10: =ROUND((C10/B10)^0.5,1) -> 203.2 | H10: =ROUND((D10/B10)^0.5,1) -> 165.2 | I10: =ROUND(0.00785*B10,3) -> 221.871 | J10: =HM!J10 -> 482 | K10: =2*HM!K10 -> 600 | L10: =HM!L10 -> 11 | M10: =HM!M10 -> 15 | N10: =HM!K10 -> 300 | O10: =M10 -> 15
A11: ="2"&HM!A11 -> 2HM488X300 | B11: =2*HM!B11 -> 31863.8 | C11: =2*HM!C11 -> 1378638220 | D11: =ROUND(2*HM!D11+HM!B11*HM!K11^2/2,2) -> 879061796 | E11: =ROUND(C11/J11*2,1) -> 5650156.6 | F11: =ROUND(D11/K11*2,1) -> 2930206 | G11: =ROUND((C11/B11)^0.5,1) -> 208 | H11: =ROUND((D11/B11)^0.5,1) -> 166.1 | I11: =ROUND(0.00785*B11,3) -> 250.131 | J11: =HM!J11 -> 488 | K11: =2*HM!K11 -> 600 | L11: =HM!L11 -> 11 | M11: =HM!M11 -> 18 | N11: =HM!K11 -> 300 | O11: =M11 -> 18
A12: ="2"&HM!A12 -> 2HM544X300 | B12: =2*HM!B12 -> 29627.8 | C12: =2*HM!C12 -> 1529205700 | D12: =ROUND(2*HM!D12+HM!B12*HM!K12^2/2,2) -> 801765550 | E12: =ROUND(C12/J12*2,1) -> 5622079.8 | F12: =ROUND(D12/K12*2,1) -> 2672551.8 | G12: =ROUND((C12/B12)^0.5,1) -> 227.2 | H12: =ROUND((D12/B12)^0.5,1) -> 164.5 | I12: =ROUND(0.00785*B12,3) -> 232.578 | J12: =HM!J12 -> 544 | K12: =2*HM!K12 -> 600 | L12: =HM!L12 -> 11 | M12: =HM!M12 -> 15 | N12: =HM!K12 -> 300 | O12: =M12 -> 15
A13: ="2"&HM!A13 -> 2HM550X300 | B13: =2*HM!B13 -> 33227.8 | C13: =2*HM!C13 -> 1798496500 | D13: =ROUND(2*HM!D13+HM!B13*HM!K13^2/2,2) -> 909765550 | E13: =ROUND(C13/J13*2,1) -> 6539987.3 | F13: =ROUND(D13/K13*2,1) -> 3032551.8 | G13: =ROUND((C13/B13)^0.5,1) -> 232.7 | H13: =ROUND((D13/B13)^0.5,1) -> 165.5 | I13: =ROUND(0.00785*B13,3) -> 260.838 | J13: =HM!J13 -> 550 | K13: =2*HM!K13 -> 600 | L13: =HM!L13 -> 11 | M13: =HM!M13 -> 18 | N13: =HM!K13 -> 300 | O13: =M13 -> 18
... A16: ="2"&HM!A16 -> 2HM594X302 | B16: =2*HM!B16 -> 43447.8 | C16: =2*HM!C16 -> 2673371000 | D16: =ROUND(2*HM!D16+HM!B16*HM!K16^2/2,2) -> 1.2021066e+09 | E16: =ROUND(C16/J16*2,1) -> 9001249.2 | F16: =ROUND(D16/K16*2,1) -> 3980485.3 | G16: =ROUND((C16/B16)^0.5,1) -> 248.1 | H16: =ROUND((D16/B16)^0.5,1) -> 166.3 | I16: =ROUND(0.00785*B16,3) -> 341.065 | J16: =HM!J16 -> 594 | K16: =2*HM!K16 -> 604 | L16: =HM!L16 -> 14 | M16: =HM!M16 -> 23 | N16: =HM!K16 -> 302 | O16: =M16 -> 23

Sheet HN
A1: 型号 | B1: A | C1: Ix | D1: Iy | E1: Wx | F1: Wy | G1: ix | H1: iy | I1: 每延米重 | J1: H | K1: B | L1: tw | M1: tf1 | N1: r1
A2: HN100X50 | B2: 1190.6 | C2: 1883909.3 | D2: 148076.1 | E2: =ROUND(C2/J2*2,1) -> 37678.2 | F2: =ROUND(D2/K2*2,1) -> 5923 | G2: =ROUND((C2/B2)^0.5,1) -> 39.8 | H2: =ROUND((D2/B2)^0.5,1) -> 11.2 | I2: =ROUND(0.00785*B2,3) -> 9.346 | J2: 100 | K2: 50 | L2: 5 | M2: 7 | N2: 8
A3: HN125X60 | B3: 1674.6 | C3: 4105702.2 | D3: 291590.9 | E3: =ROUND(C3/J3*2,1) -> 65691.2 | F3: =ROUND(D3/K3*2,1) -> 9719.7 | G3: =ROUND((C3/B3)^0.5,1) -> 49.5 | H3: =ROUND((D3/B3)^0.5,1) -> 13.2 | I3: =ROUND(0.00785*B3,3) -> 13.146 | J3: 125 | K3: 60 | L3: 6 | M3: 8 | N3: 8
A4: HN150X75 | B4: 1790.6 | C4: 6685009 | D4: 494951.1 | E4: =ROUND(C4/J4*2,1) -> 89133.5 | F4: =ROUND(D4/K4*2,1) -> 13198.7 | G4: =ROUND((C4/B4)^0.5,1) -> 61.1 | H4: =ROUND((D4/B4)^0.5,1) -> 16.6 | I4: =ROUND(0.00785*B4,3) -> 14.056 | J4: 150 | K4: 75 | L4: 5 | M4: 7 | N4: 8
A5: HN175X90 | B5: 2295.6 | C5: 12087419 | D5: 975003.2 | E5: =ROUND(C5/J5*2,1) -> 138141.9 | F5: =ROUND(D5/K5*2,1) -> 21666.7 | G5: =ROUND((C5/B5)^0.5,1) -> 72.6 | H5: =ROUND((D5/B5)^0.5,1) -> 20.6 | I5: =ROUND(0.00785*B5,3) -> 18.02 | J5: 175 | K5: 90 | L5: 5 | M5: 8 | N5: 8
A6: HN198X99 | B6: 2274.6 | C6: 15474175 | D6: 1134630.1 | E6: =ROUND(C6/J6*2,1) -> 156304.8 | F6: =ROUND(D6/K6*2,1) -> 22921.8 | G6: =ROUND((C6/B6)^0.5,1) -> 82.5 | H6: =ROUND((D6/B6)^0.5,1) -> 22.3 | I6: =ROUND(0.00785*B6,3) -> 17.856 | J6: 198 | K6: 99 | L6: 4.5 | M6: 7 | N6: 8
A7: HN200X100 | B7: 2672.6 | C7: 18101108 | D7: 1337368.5 | E7: =ROUND(C7/J7*2,1) -> 181011.1 | F7: =ROUND(D7/K7*2,1) -> 26747.4 | G7: =ROUND((C7/B7)^0.5,1) -> 82.3 | H7: =ROUND((D7/B7)^0.5,1) -> 22.4 | I7: =ROUND(0.00785*B7,3) -> 20.98 | J7: 200 | K7: 100 | L7: 5.5 | M7: 8 | N7: 8
A8: HN248X124 | B8: 3204.6 | C8: 34571758 | D8: 2545928.9 | E8: =ROUND(C8/J8*2,1) -> 278804.5 | F8: =ROUND(D8/K8*2,1) -> 41063.4 | G8: =ROUND((C8/B8)^0.5,1) -> 103.9 | H8: =ROUND((D8/B8)^0.5,1) -> 28.2 | I8: =ROUND(0.00785*B8,3) -> 25.156 | J8: 248 | K8: 124 | L8: 5 | M8: 8 | N8: 8
A9: HN250X125 | B9: 3702.6 | C9: 39717924 | D9: 2935492.4 | E9: =ROUND(C9/J9*2,1) -> 317743.4 | F9: =ROUND(D9/K9*2,1) -> 46967.9 | G9: =ROUND((C9/B9)^0.5,1) -> 103.6 | H9: =ROUND((D9/B9)^0.5,1) -> 28.2 | I9: =ROUND(0.00785*B9,3) -> 29.065 | J9: 250 | K9: 125 | L9: 6 | M9: 9 | N9: 8
A10: HN298X149 | B10: 4094.9 | C10: 63457470 | D10: 4421170.5 | E10: =ROUND(C10/J10*2,1) -> 425889.1 | F10: =ROUND(D10/K10*2,1) -> 59344.6 | G10: =ROUND((C10/B10)^0.5,1) -> 124.5 | H10: =ROUND((D10/B10)^0.5,1) -> 32.9 | I10: =ROUND(0.00785*B10,3) -> 32.145 | J10: 298 | K10: 149 | L10: 5.5 | M10: 8 | N10: 13
A11: HN300X150 | B11: 4692.9 | C11: 72367869 | D11: 5076590.7 | E11: =ROUND(C11/J11*2,1) -> 482452.5 | F11: =ROUND(D11/K11*2,1) -> 67687.9 | G11: =ROUND((C11/B11)^0.5,1) -> 124.2 | H11: =ROUND((D11/B11)^0.5,1) -> 32.9 | I11: =ROUND(0.00785*B11,3) -> 36.839 | J11: 300 | K11: 150 | L11: 6.5 | M11: 9 | N11: 13
A12: HN346X174 | B12: 5259.9 | C12: 110731260 | D12: 7915079.6 | E12: =ROUND(C12/J12*2,1) -> 640065.1 | F12: =ROUND(D12/K12*2,1) -> 90977.9 | G12: =ROUND((C12/B12)^0.5,1) -> 145.1 | H12: =ROUND((D12/B12)^0.5,1) -> 38.8 | I12: =ROUND(0.00785*B12,3) -> 41.29 | J12: 346 | K12: 174 | L12: 6 | M12: 9 | N12: 13
A13: HN350X175 | B13: 6305.9 | C13: 135376510 | D13: 9843050.7 | E13: =ROUND(C13/J13*2,1) -> 773580.1 | F13: =ROUND(D13/K13*2,1) -> 112492 | G13: =ROUND((C13/B13)^0.5,1) -> 146.5 | H13: =ROUND((D13/B13)^0.5,1) -> 39.5 | I13: =ROUND(0.00785*B13,3) -> 49.501 | J13: 350 | K13: 175 | L13: 7 | M13: 11 | N13: 13
... A60: HN1008X302 | B60: 43954.6 | C60: 7126212000 | D60: 184411680 | E60: =ROUND(C60/J60*2,1) -> 14139310 | F60: =ROUND(D60/K60*2,1) -> 1221269.4 | G60: =ROUND((C60/B60)^0.5,1) -> 402.6 | H60: =ROUND((D60/B60)^0.5,1) -> 64.8 | I60: =ROUND(0.00785*B60,3) -> 345.044 | J60: 1008 | K60: 302 | L60: 21 | M60: 40 | N60: 18

Sheet 2HN
A1: 型号 | B1: A | C1: Ix | D1: Iy | E1: Wx | F1: Wy | G1: ix | H1: iy | I1: 每延米重 | J1: H | K1: B | L1: tw | M1: tf1 | N1: C | O1: tf2
A2: ="2"&HN!A2 -> 2HN100X50 | B2: =2*HN!B2 -> 2381.2 | C2: =2*HN!C2 -> 3767818.6 | D2: =ROUND(HN!D2*2+HN!B2*HN!K2^2/2,1) -> 1784402.2 | E2: =ROUND(C2/J2*2,1) -> 75356.4 | F2: =ROUND(D2/K2*2,1) -> 35688 | G2: =ROUND((C2/B2)^0.5,1) -> 39.8 | H2: =ROUND((D2/B2)^0.5,1) -> 27.4 | I2: =ROUND(0.00785*B2,3) -> 18.692 | J2: =HN!J2 -> 100 | K2: =HN!K2*2 -> 100 | L2: =HN!L2 -> 5 | M2: =HN!M2 -> 7 | N2: =HN!K2 -> 50 | O2: =M2 -> 7
A3: ="2"&HN!A3 -> 2HN125X60 | B3: =2*HN!B3 -> 3349.2 | C3: =2*HN!C3 -> 8211404.4 | D3: =ROUND(HN!D3*2+HN!B3*HN!K3^2/2,1) -> 3597461.8 | E3: =ROUND(C3/J3*2,1) -> 131382.5 | F3: =ROUND(D3/K3*2,1) -> 59957.7 | G3: =ROUND((C3/B3)^0.5,1) -> 49.5 | H3: =ROUND((D3/B3)^0.5,1) -> 32.8 | I3: =ROUND(0.00785*B3,3) -> 26.291 | J3: =HN!J3 -> 125 | K3: =HN!K3*2 -> 120 | L3: =HN!L3 -> 6 | M3: =HN!M3 -> 8 | N3: =HN!K3 -> 60 | O3: =M3 -> 8
A4: ="2"&HN!A4 -> 2HN150X75 | B4: =2*HN!B4 -> 3581.2 | C4: =2*HN!C4 -> 13370018 | D4: =ROUND(HN!D4*2+HN!B4*HN!K4^2/2,1) -> 6025964.7 | E4: =ROUND(C4/J4*2,1) -> 178266.9 | F4: =ROUND(D4/K4*2,1) -> 80346.2 | G4: =ROUND((C4/B4)^0.5,1) -> 61.1 | H4: =ROUND((D4/B4)^0.5,1) -> 41 | I4: =ROUND(0.00785*B4,3) -> 28.112 | J4: =HN!J4 -> 150 | K4: =HN!K4*2 -> 150 | L4: =HN!L4 -> 5 | M4: =HN!M4 -> 7 | N4: =HN!K4 -> 75 | O4: =M4 -> 7
A5: ="2"&HN!A5 -> 2HN175X90 | B5: =2*HN!B5 -> 4591.2 | C5: =2*HN!C5 -> 24174838 | D5: =ROUND(HN!D5*2+HN!B5*HN!K5^2/2,1) -> 11247186 | E5: =ROUND(C5/J5*2,1) -> 276283.9 | F5: =ROUND(D5/K5*2,1) -> 124968.7 | G5: =ROUND((C5/B5)^0.5,1) -> 72.6 | H5: =ROUND((D5/B5)^0.5,1) -> 49.5 | I5: =ROUND(0.00785*B5,3) -> 36.041 | J5: =HN!J5 -> 175 | K5: =HN!K5*2 -> 180 | L5: =HN!L5 -> 5 | M5: =HN!M5 -> 8 | N5: =HN!K5 -> 90 | O5: =M5 -> 8
A6: ="2"&HN!A6 -> 2HN198X99 | B6: =2*HN!B6 -> 4549.2 | C6: =2*HN!C6 -> 30948350 | D6: =ROUND(HN!D6*2+HN!B6*HN!K6^2/2,1) -> 13415938 | E6: =ROUND(C6/J6*2,1) -> 312609.6 | F6: =ROUND(D6/K6*2,1) -> 135514.5 | G6: =ROUND((C6/B6)^0.5,1) -> 82.5 | H6: =ROUND((D6/B6)^0.5,1) -> 54.3 | I6: =ROUND(0.00785*B6,3) -> 35.711 | J6: =HN!J6 -> 198 | K6: =HN!K6*2 -> 198 | L6: =HN!L6 -> 4.5 | M6: =HN!M6 -> 7 | N6: =HN!K6 -> 99 | O6: =M6 -> 7
A7: ="2"&HN!A7 -> 2HN200X100 | B7: =2*HN!B7 -> 5345.2 | C7: =2*HN!C7 -> 36202216 | D7: =ROUND(HN!D7*2+HN!B7*HN!K7^2/2,1) -> 16037737 | E7: =ROUND(C7/J7*2,1) -> 362022.2 | F7: =ROUND(D7/K7*2,1) -> 160377.4 | G7: =ROUND((C7/B7)^0.5,1) -> 82.3 | H7: =ROUND((D7/B7)^0.5,1) -> 54.8 | I7: =ROUND(0.00785*B7,3) -> 41.96 | J7: =HN!J7 -> 200 | K7: =HN!K7*2 -> 200 | L7: =HN!L7 -> 5.5 | M7: =HN!M7 -> 8 | N7: =HN!K7 -> 100 | O7: =M7 -> 8
A8: ="2"&HN!A8 -> 2HN248X124 | B8: =2*HN!B8 -> 6409.2 | C8: =2*HN!C8 -> 69143516 | D8: =ROUND(HN!D8*2+HN!B8*HN!K8^2/2,1) -> 29728823 | E8: =ROUND(C8/J8*2,1) -> 557609 | F8: =ROUND(D8/K8*2,1) -> 239748.6 | G8: =ROUND((C8/B8)^0.5,1) -> 103.9 | H8: =ROUND((D8/B8)^0.5,1) -> 68.1 | I8: =ROUND(0.00785*B8,3) -> 50.312 | J8: =HN!J8 -> 248 | K8: =HN!K8*2 -> 248 | L8: =HN!L8 -> 5 | M8: =HN!M8 -> 8 | N8: =HN!K8 -> 124 | O8: =M8 -> 8
A9: ="2"&HN!A9 -> 2HN250X125 | B9: =2*HN!B9 -> 7405.2 | C9: =2*HN!C9 -> 79435848 | D9: =ROUND(HN!D9*2+HN!B9*HN!K9^2/2,1) -> 34797547 | E9: =ROUND(C9/J9*2,1) -> 635486.8 | F9: =ROUND(D9/K9*2,1) -> 278380.4 | G9: =ROUND((C9/B9)^0.5,1) -> 103.6 | H9: =ROUND((D9/B9)^0.5,1) -> 68.5 | I9: =ROUND(0.00785*B9,3) -> 58.131 | J9: =HN!J9 -> 250 | K9: =HN!K9*2 -> 250 | L9: =HN!L9 -> 6 | M9: =HN!M9 -> 9 | N9: =HN!K9 -> 125 | O9: =M9 -> 9
A10: ="2"&HN!A10 -> 2HN298X149 | B10: =2*HN!B10 -> 8189.8 | C10: =2*HN!C10 -> 126914940 | D10: =ROUND(HN!D10*2+HN!B10*HN!K10^2/2,1) -> 54297778 | E10: =ROUND(C10/J10*2,1) -> 851778.1 | F10: =ROUND(D10/K10*2,1) -> 364414.6 | G10: =ROUND((C10/B10)^0.5,1) -> 124.5 | H10: =ROUND((D10/B10)^0.5,1) -> 81.4 | I10: =ROUND(0.00785*B10,3) -> 64.29 | J10: =HN!J10 -> 298 | K10: =HN!K10*2 -> 298 | L10: =HN!L10 -> 5.5 | M10: =HN!M10 -> 8 | N10: =HN!K10 -> 149 | O10: =M10 -> 8
A11: ="2"&HN!A11 -> 2HN300X150 | B11: =2*HN!B11 -> 9385.8 | C11: =2*HN!C11 -> 144735738 | D11: =ROUND(HN!D11*2+HN!B11*HN!K11^2/2,1) -> 62948306 | E11: =ROUND(C11/J11*2,1) -> 964904.9 | F11: =ROUND(D11/K11*2,1) -> 419655.4 | G11: =ROUND((C11/B11)^0.5,1) -> 124.2 | H11: =ROUND((D11/B11)^0.5,1) -> 81.9 | I11: =ROUND(0.00785*B11,3) -> 73.679 | J11: =HN!J11 -> 300 | K11: =HN!K11*2 -> 300 | L11: =HN!L11 -> 6.5 | M11: =HN!M11 -> 9 | N11: =HN!K11 -> 150 | O11: =M11 -> 9
A12: ="2"&HN!A12 -> 2HN346X174 | B12: =2*HN!B12 -> 10519.8 | C12: =2*HN!C12 -> 221462520 | D12: =ROUND(HN!D12*2+HN!B12*HN!K12^2/2,1) -> 95454525 | E12: =ROUND(C12/J12*2,1) -> 1280130.2 | F12: =ROUND(D12/K12*2,1) -> 548589.2 | G12: =ROUND((C12/B12)^0.5,1) -> 145.1 | H12: =ROUND((D12/B12)^0.5,1) -> 95.3 | I12: =ROUND(0.00785*B12,3) -> 82.58 | J12: =HN!J12 -> 346 | K12: =HN!K12*2 -> 348 | L12: =HN!L12 -> 6 | M12: =HN!M12 -> 9 | N12: =HN!K12 -> 174 | O12: =M12 -> 9
A13: ="2"&HN!A13 -> 2HN350X175 | B13: =2*HN!B13 -> 12611.8 | C13: =2*HN!C13 -> 270753020 | D13: =ROUND(HN!D13*2+HN!B13*HN!K13^2/2,1) -> 1.162452e+08 | E13: =ROUND(C13/J13*2,1) -> 1547160.1 | F13: =ROUND(D13/K13*2,1) -> 664258.3 | G13: =ROUND((C13/B13)^0.5,1) -> 146.5 | H13: =ROUND((D13/B13)^0.5,1) -> 96 | I13: =ROUND(0.00785*B13,3) -> 99.003 | J13: =HN!J13 -> 350 | K13: =HN!K13*2 -> 350 | L13: =HN!L13 -> 7 | M13: =HN!M13 -> 11 | N13: =HN!K13 -> 175 | O13: =M13 -> 11
... A60: ="2"&HN!A60 -> 2HN1008X302 | B60: =2*HN!B60 -> 87909.2 | C60: =2*HN!C60 -> 14252424000 | D60: =ROUND(HN!D60*2+HN!B60*HN!K60^2/2,1) -> 2.373241e+09 | E60: =ROUND(C60/J60*2,1) -> 28278619 | F60: =ROUND(D60/K60*2,1) -> 7858414 | G60: =ROUND((C60/B60)^0.5,1) -> 402.6 | H60: =ROUND((D60/B60)^0.5,1) -> 164.3 | I60: =ROUND(0.00785*B60,3) -> 690.087 | J60: =HN!J60 -> 1008 | K60: =HN!K60*2 -> 604 | L60: =HN!L60 -> 21 | M60: =HN!M60 -> 40 | N60: =HN!K60 -> 302 | O60: =M60 -> 40

Sheet HW
A1: 型号 | B1: A | C1: Ix | D1: Iy | E1: Wx | F1: Wy | G1: ix | H1: iy | I1: 每延米重 | J1: H | K1: B | L1: tw | M1: tf1 | N1: r1
A2: HW100X100 | B2: 2164.6 | C2: 3788020.7 | D2: 1336474.2 | E2: =ROUND(C2/J2*2,1) -> 75760.4 | F2: =ROUND(D2/K2*2,1) -> 26729.5 | G2: =ROUND((C2/B2)^0.5,1) -> 41.8 | H2: =ROUND((D2/B2)^0.5,1) -> 24.8 | I2: =ROUND(0.00785*B2,3) -> 16.992 | J2: 100 | K2: 100 | L2: 6 | M2: 8 | N2: 8
A3: HW125X125 | B3: 3006.1 | C3: 8409149.8 | D3: 2933917.5 | E3: =ROUND(C3/J3*2,1) -> 134546.4 | F3: =ROUND(D3/K3*2,1) -> 46942.7 | G3: =ROUND((C3/B3)^0.5,1) -> 52.9 | H3: =ROUND((D3/B3)^0.5,1) -> 31.2 | I3: =ROUND(0.00785*B3,3) -> 23.598 | J3: 125 | K3: 125 | L3: 6.5 | M3: 9 | N3: 8
A4: HW150X150 | B4: 3970.6 | C4: 16247862 | D4: 5630657 | E4: =ROUND(C4/J4*2,1) -> 216638.2 | F4: =ROUND(D4/K4*2,1) -> 75075.4 | G4: =ROUND((C4/B4)^0.5,1) -> 64 | H4: =ROUND((D4/B4)^0.5,1) -> 37.7 | I4: =ROUND(0.00785*B4,3) -> 31.169 | J4: 150 | K4: 150 | L4: 7 | M4: 10 | N4: 8
A5: HW175X175 | B5: 5157.4 | C5: 29027628 | D5: 9839591.7 | E5: =ROUND(C5/J5*2,1) -> 331744.3 | F5: =ROUND(D5/K5*2,1) -> 112452.5 | G5: =ROUND((C5/B5)^0.5,1) -> 75 | H5: =ROUND((D5/B5)^0.5,1) -> 43.7 | I5: =ROUND(0.00785*B5,3) -> 40.486 | J5: 175 | K5: 175 | L5: 7.5 | M5: 11 | N5: 13
A6: HW200X200 | B6: 6367.9 | C6: 47258999 | D6: 16016759 | E6: =ROUND(C6/J6*2,1) -> 472590 | F6: =ROUND(D6/K6*2,1) -> 160167.6 | G6: =ROUND((C6/B6)^0.5,1) -> 86.1 | H6: =ROUND((D6/B6)^0.5,1) -> 50.2 | I6: =ROUND(0.00785*B6,3) -> 49.988 | J6: 200 | K6: 200 | L6: 8 | M6: 12 | N6: 13
A7: HW200X204 | B7: 7167.9 | C7: 49925666 | D7: 17019101 | E7: =ROUND(C7/J7*2,1) -> 499256.7 | F7: =ROUND(D7/K7*2,1) -> 166853.9 | G7: =ROUND((C7/B7)^0.5,1) -> 83.5 | H7: =ROUND((D7/B7)^0.5,1) -> 48.7 | I7: =ROUND(0.00785*B7,3) -> 56.268 | J7: 200 | K7: 204 | L7: 12 | M7: 12 | N7: 13
A8: HW244X252 | B8: 8145.9 | C8: 87193059 | D8: 29376486 | E8: =ROUND(C8/J8*2,1) -> 714697.2 | F8: =ROUND(D8/K8*2,1) -> 233146.7 | G8: =ROUND((C8/B8)^0.5,1) -> 103.5 | H8: =ROUND((D8/B8)^0.5,1) -> 60.1 | I8: =ROUND(0.00785*B8,3) -> 63.945 | J8: 244 | K8: 252 | L8: 11 | M8: 11 | N8: 13
A9: HW250X250 | B9: 9157.9 | C9: 107651430 | D9: 36482244 | E9: =ROUND(C9/J9*2,1) -> 861211.4 | F9: =ROUND(D9/K9*2,1) -> 291858 | G9: =ROUND((C9/B9)^0.5,1) -> 108.4 | H9: =ROUND((D9/B9)^0.5,1) -> 63.1 | I9: =ROUND(0.00785*B9,3) -> 71.89 | J9: 250 | K9: 250 | L9: 9 | M9: 14 | N9: 13
A10: HW250X255 | B10: 10407.9 | C10: 114161840 | D10: 38758137 | E10: =ROUND(C10/J10*2,1) -> 913294.7 | F10: =ROUND(D10/K10*2,1) -> 303985.4 | G10: =ROUND((C10/B10)^0.5,1) -> 104.7 | H10: =ROUND((D10/B10)^0.5,1) -> 61 | I10: =ROUND(0.00785*B10,3) -> 81.702 | J10: 250 | K10: 255 | L10: 14 | M10: 14 | N10: 13
A11: HW294X302 | B11: 10647.9 | C11: 166651240 | D11: 55140525 | E11: =ROUND(C11/J11*2,1) -> 1133681.9 | F11: =ROUND(D11/K11*2,1) -> 365169 | G11: =ROUND((C11/B11)^0.5,1) -> 125.1 | H11: =ROUND((D11/B11)^0.5,1) -> 72 | I11: =ROUND(0.00785*B11,3) -> 83.586 | J11: 294 | K11: 302 | L11: 12 | M11: 12 | N11: 13
A12: HW300X300 | B12: 11859.9 | C12: 202111270 | D12: 67534179 | E12: =ROUND(C12/J12*2,1) -> 1347408.5 | F12: =ROUND(D12/K12*2,1) -> 450227.9 | G12: =ROUND((C12/B12)^0.5,1) -> 130.5 | H12: =ROUND((D12/B12)^0.5,1) -> 75.5 | I12: =ROUND(0.00785*B12,3) -> 93.1 | J12: 300 | K12: 300 | L12: 10 | M12: 15 | N12: 13
A13: HW300X305 | B13: 13359.9 | C13: 213361270 | D13: 71026653 | E13: =ROUND(C13/J13*2,1) -> 1422408.5 | F13: =ROUND(D13/K13*2,1) -> 465748.5 | G13: =ROUND((C13/B13)^0.5,1) -> 126.4 | H13: =ROUND((D13/B13)^0.5,1) -> 72.9 | I13: =ROUND(0.00785*B13,3) -> 104.875 | J13: 300 | K13: 305 | L13: 15 | M13: 15 | N13: 13
... A30: HW502X470 | B30: 32998 | C30: 1514197700 | D30: 433013350 | E30: =ROUND(C30/J30*2,1) -> 6032660.2 | F30: =ROUND(D30/K30*2,1) -> 1842610 | G30: =ROUND((C30/B30)^0.5,1) -> 214.2 | H30: =ROUND((D30/B30)^0.5,1) -> 114.6 | I30: =ROUND(0.00785*B30,3) -> 259.034 | J30: 502 | K30: 470 | L30: 20 | M30: 25 | N30: 22

Sheet 2HW
A1: 型号 | B1: A | C1: Ix | D1: Iy | E1: Wx | F1: Wy | G1: ix | H1: iy | I1: 每延米重 | J1: H | K1: B | L1: tw | M1: tf1 | N1: C | O1: tf2
A2: ="2"&HW!A2 -> 2HW100X100 | B2: =2*HW!B2 -> 4329.2 | C2: =2*HW!C2 -> 7576041.4 | D2: =ROUND(2*HW!D2+HW!B2*HW!K2^2/2,1) -> 13495948 | E2: =ROUND(C2/J2*2,1) -> 151520.8 | F2: =ROUND(D2/K2*2,1) -> 134959.5 | G2: =ROUND((C2/B2)^0.5,1) -> 41.8 | H2: =ROUND((D2/B2)^0.5,1) -> 55.8 | I2: =ROUND(0.00785*B2,3) -> 33.984 | J2: =HW!J2 -> 100 | K2: =2*HW!K2 -> 200 | L2: =HW!L2 -> 6 | M2: =HW!M2 -> 8 | N2: =HW!K2 -> 100 | O2: =M2 -> 8
A3: ="2"&HW!A3 -> 2HW125X125 | B3: =2*HW!B3 -> 6012.2 | C3: =2*HW!C3 -> 16818300 | D3: =ROUND(2*HW!D3+HW!B3*HW!K3^2/2,1) -> 29352991 | E3: =ROUND(C3/J3*2,1) -> 269092.8 | F3: =ROUND(D3/K3*2,1) -> 234823.9 | G3: =ROUND((C3/B3)^0.5,1) -> 52.9 | H3: =ROUND((D3/B3)^0.5,1) -> 69.9 | I3: =ROUND(0.00785*B3,3) -> 47.196 | J3: =HW!J3 -> 125 | K3: =2*HW!K3 -> 250 | L3: =HW!L3 -> 6.5 | M3: =HW!M3 -> 9 | N3: =HW!K3 -> 125 | O3: =M3 -> 9
A4: ="2"&HW!A4 -> 2HW150X150 | B4: =2*HW!B4 -> 7941.2 | C4: =2*HW!C4 -> 32495724 | D4: =ROUND(2*HW!D4+HW!B4*HW!K4^2/2,1) -> 55930564 | E4: =ROUND(C4/J4*2,1) -> 433276.3 | F4: =ROUND(D4/K4*2,1) -> 372870.4 | G4: =ROUND((C4/B4)^0.5,1) -> 64 | H4: =ROUND((D4/B4)^0.5,1) -> 83.9 | I4: =ROUND(0.00785*B4,3) -> 62.338 | J4: =HW!J4 -> 150 | K4: =2*HW!K4 -> 300 | L4: =HW!L4 -> 7 | M4: =HW!M4 -> 10 | N4: =HW!K4 -> 150 | O4: =M4 -> 10
A5: ="2"&HW!A5 -> 2HW175X175 | B5: =2*HW!B5 -> 10314.8 | C5: =2*HW!C5 -> 58055256 | D5: =ROUND(2*HW!D5+HW!B5*HW!K5^2/2,1) -> 98651871 | E5: =ROUND(C5/J5*2,1) -> 663488.6 | F5: =ROUND(D5/K5*2,1) -> 563725 | G5: =ROUND((C5/B5)^0.5,1) -> 75 | H5: =ROUND((D5/B5)^0.5,1) -> 97.8 | I5: =ROUND(0.00785*B5,3) -> 80.971 | J5: =HW!J5 -> 175 | K5: =2*HW!K5 -> 350 | L5: =HW!L5 -> 7.5 | M5: =HW!M5 -> 11 | N5: =HW!K5 -> 175 | O5: =M5 -> 11
A6: ="2"&HW!A6 -> 2HW200X200 | B6: =2*HW!B6 -> 12735.8 | C6: =2*HW!C6 -> 94517998 | D6: =ROUND(2*HW!D6+HW!B6*HW!K6^2/2,1) -> 159391518 | E6: =ROUND(C6/J6*2,1) -> 945180 | F6: =ROUND(D6/K6*2,1) -> 796957.6 | G6: =ROUND((C6/B6)^0.5,1) -> 86.1 | H6: =ROUND((D6/B6)^0.5,1) -> 111.9 | I6: =ROUND(0.00785*B6,3) -> 99.976 | J6: =HW!J6 -> 200 | K6: =2*HW!K6 -> 400 | L6: =HW!L6 -> 8 | M6: =HW!M6 -> 12 | N6: =HW!K6 -> 200 | O6: =M6 -> 12
A7: ="2"&HW!A7 -> 2HW200X204 | B7: =2*HW!B7 -> 14335.8 | C7: =2*HW!C7 -> 99851332 | D7: =ROUND(2*HW!D7+HW!B7*HW!K7^2/2,1) -> 1.8318787e+08 | E7: =ROUND(C7/J7*2,1) -> 998513.3 | F7: =ROUND(D7/K7*2,1) -> 897979.7 | G7: =ROUND((C7/B7)^0.5,1) -> 83.5 | H7: =ROUND((D7/B7)^0.5,1) -> 113 | I7: =ROUND(0.00785*B7,3) -> 112.536 | J7: =HW!J7 -> 200 | K7: =2*HW!K7 -> 408 | L7: =HW!L7 -> 12 | M7: =HW!M7 -> 12 | N7: =HW!K7 -> 204 | O7: =M7 -> 12
A8: ="2"&HW!A8 -> 2HW244X252 | B8: =2*HW!B8 -> 16291.8 | C8: =2*HW!C8 -> 174386118 | D8: =ROUND(2*HW!D8+HW!B8*HW!K8^2/2,1) -> 3.1740159e+08 | E8: =ROUND(C8/J8*2,1) -> 1429394.4 | F8: =ROUND(D8/K8*2,1) -> 1259530.1 | G8: =ROUND((C8/B8)^0.5,1) -> 103.5 | H8: =ROUND((D8/B8)^0.5,1) -> 139.6 | I8: =ROUND(0.00785*B8,3) -> 127.891 | J8: =HW!J8 -> 244 | K8: =2*HW!K8 -> 504 | L8: =HW!L8 -> 11 | M8: =HW!M8 -> 11 | N8: =HW!K8 -> 252 | O8: =M8 -> 11
A9: ="2"&HW!A9 -> 2HW250X250 | B9: =2*HW!B9 -> 18315.8 | C9: =2*HW!C9 -> 215302860 | D9: =ROUND(2*HW!D9+HW!B9*HW!K9^2/2,1) -> 359148863 | E9: =ROUND(C9/J9*2,1) -> 1722422.9 | F9: =ROUND(D9/K9*2,1) -> 1436595.5 | G9: =ROUND((C9/B9)^0.5,1) -> 108.4 | H9: =ROUND((D9/B9)^0.5,1) -> 140 | I9: =ROUND(0.00785*B9,3) -> 143.779 | J9: =HW!J9 -> 250 | K9: =2*HW!K9 -> 500 | L9: =HW!L9 -> 9 | M9: =HW!M9 -> 14 | N9: =HW!K9 -> 250 | O9: =M9 -> 14
A10: ="2"&HW!A10 -> 2HW250X255 | B10: =2*HW!B10 -> 20815.8 | C10: =2*HW!C10 -> 228323680 | D10: =ROUND(2*HW!D10+HW!B10*HW!K10^2/2,1) -> 4.1590312e+08 | E10: =ROUND(C10/J10*2,1) -> 1826589.4 | F10: =ROUND(D10/K10*2,1) -> 1630992.6 | G10: =ROUND((C10/B10)^0.5,1) -> 104.7 | H10: =ROUND((D10/B10)^0.5,1) -> 141.4 | I10: =ROUND(0.00785*B10,3) -> 163.404 | J10: =HW!J10 -> 250 | K10: =2*HW!K10 -> 510 | L10: =HW!L10 -> 14 | M10: =HW!M10 -> 14 | N10: =HW!K10 -> 255 | O10: =M10 -> 14
A11: ="2"&HW!A11 -> 2HW294X302 | B11: =2*HW!B11 -> 21295.8 | C11: =2*HW!C11 -> 333302480 | D11: =ROUND(2*HW!D11+HW!B11*HW!K11^2/2,1) -> 5.9584659e+08 | E11: =ROUND(C11/J11*2,1) -> 2267363.8 | F11: =ROUND(D11/K11*2,1) -> 1973001.9 | G11: =ROUND((C11/B11)^0.5,1) -> 125.1 | H11: =ROUND((D11/B11)^0.5,1) -> 167.3 | I11: =ROUND(0.00785*B11,3) -> 167.172 | J11: =HW!J11 -> 294 | K11: =2*HW!K11 -> 604 | L11: =HW!L11 -> 12 | M11: =HW!M11 -> 12 | N11: =HW!K11 -> 302 | O11: =M11 -> 12
A12: ="2"&HW!A12 -> 2HW300X300 | B12: =2*HW!B12 -> 23719.8 | C12: =2*HW!C12 -> 404222540 | D12: =ROUND(2*HW!D12+HW!B12*HW!K12^2/2,1) -> 668763858 | E12: =ROUND(C12/J12*2,1) -> 2694816.9 | F12: =ROUND(D12/K12*2,1) -> 2229212.9 | G12: =ROUND((C12/B12)^0.5,1) -> 130.5 | H12: =ROUND((D12/B12)^0.5,1) -> 167.9 | I12: =ROUND(0.00785*B12,3) -> 186.2 | J12: =HW!J12 -> 300 | K12: =2*HW!K12 -> 600 | L12: =HW!L12 -> 10 | M12: =HW!M12 -> 15 | N12: =HW!K12 -> 300 | O12: =M12 -> 15
A13: ="2"&HW!A13 -> 2HW300X305 | B13: =2*HW!B13 -> 26719.8 | C13: =2*HW!C13 -> 426722540 | D13: =ROUND(2*HW!D13+HW!B13*HW!K13^2/2,1) -> 7.6345565e+08 | E13: =ROUND(C13/J13*2,1) -> 2844816.9 | F13: =ROUND(D13/K13*2,1) -> 2503133.3 | G13: =ROUND((C13/B13)^0.5,1) -> 126.4 | H13: =ROUND((D13/B13)^0.5,1) -> 169 | I13: =ROUND(0.00785*B13,3) -> 209.75 | J13: =HW!J13 -> 300 | K13: =2*HW!K13 -> 610 | L13: =HW!L13 -> 15 | M13: =HW!M13 -> 15 | N13: =HW!K13 -> 305 | O13: =M13 -> 15
... A30: ="2"&HW!A30 -> 2HW502X470 | B30: =2*HW!B30 -> 65996 | C30: =2*HW!C30 -> 3028395400 | D30: =ROUND(2*HW!D30+HW!B30*HW!K30^2/2,1) -> 4510655800 | E30: =ROUND(C30/J30*2,1) -> 12065320 | F30: =ROUND(D30/K30*2,1) -> 9597140 | G30: =ROUND((C30/B30)^0.5,1) -> 214.2 | H30: =ROUND((D30/B30)^0.5,1) -> 261.4 | I30: =ROUND(0.00785*B30,3) -> 518.069 | J30: =HW!J30 -> 502 | K30: =2*HW!K30 -> 940 | L30: =HW!L30 -> 20 | M30: =HW!M30 -> 25 | N30: =HW!K30 -> 470 | O30: =M30 -> 25

Sheet C
A1: 型号 | B1: A | C1: Ix | D1: Iy | E1: Wx | F1: Wy | G1: ix | H1: iy | I1: 每延米重 | J1: H | K1: B | L1: tw | M1: tf1 | N1: dx
A2: C5 | B2: 692.5 | C2: 260143.7 | D2: 83349.3 | E2: =ROUND(C2/J2*2,1) -> 10405.7 | F2: =ROUND(D2/K2*2,1) -> 4505.4 | G2: =ROUND((C2/B2)^0.5,1) -> 19.4 | H2: =ROUND((D2/B2)^0.5,1) -> 11 | I2: =ROUND(0.00785*B2,3) -> 5.436 | J2: 50 | K2: 37 | L2: 4.5 | M2: 7 | N2: 23.5
A3: C6.3 | B3: 844.7 | C3: 512365.8 | D3: 118950.2 | E3: =ROUND(C3/J3*2,1) -> 16265.6 | F3: =ROUND(D3/K3*2,1) -> 5947.5 | G3: =ROUND((C3/B3)^0.5,1) -> 24.6 | H3: =ROUND((D3/B3)^0.5,1) -> 11.9 | I3: =ROUND(0.00785*B3,3) -> 6.631 | J3: 63 | K3: 40 | L3: 4.8 | M3: 7.5 | N3: 26.1
A4: C8 | B4: 1024.3 | C4: 1012980.1 | D4: 166258.4 | E4: =ROUND(C4/J4*2,1) -> 25324.5 | F4: =ROUND(D4/K4*2,1) -> 7732.9 | G4: =ROUND((C4/B4)^0.5,1) -> 31.4 | H4: =ROUND((D4/B4)^0.5,1) -> 12.7 | I4: =ROUND(0.00785*B4,3) -> 8.041 | J4: 80 | K4: 43 | L4: 5 | M4: 8 | N4: 28.8
A5: C10 | B5: 1274.3 | C5: 1983048.4 | D5: 255910.7 | E5: =ROUND(C5/J5*2,1) -> 39661 | F5: =ROUND(D5/K5*2,1) -> 10662.9 | G5: =ROUND((C5/B5)^0.5,1) -> 39.4 | H5: =ROUND((D5/B5)^0.5,1) -> 14.2 | I5: =ROUND(0.00785*B5,3) -> 10.003 | J5: 100 | K5: 48 | L5: 5.3 | M5: 8.5 | N5: 32.8
A6: C12 | B6: 1535.6 | C6: 3462852.4 | D6: 374199 | E6: =ROUND(C6/J6*2,1) -> 57714.2 | F6: =ROUND(D6/K6*2,1) -> 14120.7 | G6: =ROUND((C6/B6)^0.5,1) -> 47.5 | H6: =ROUND((D6/B6)^0.5,1) -> 15.6 | I6: =ROUND(0.00785*B6,3) -> 12.054 | J6: 120 | K6: 53 | L6: 5.5 | M6: 9 | N6: 36.8
A7: C12.6 | B7: 1568.6 | C7: 3885261.6 | D7: 380128.3 | E7: =ROUND(C7/J7*2,1) -> 61670.8 | F7: =ROUND(D7/K7*2,1) -> 14344.5 | G7: =ROUND((C7/B7)^0.5,1) -> 49.8 | H7: =ROUND((D7/B7)^0.5,1) -> 15.6 | I7: =ROUND(0.00785*B7,3) -> 12.314 | J7: 126 | K7: 53 | L7: 5.5 | M7: 9 | N7: 37.1
A8: C14a | B8: 1850.9 | C8: 5637109.6 | D8: 532122.1 | E8: =ROUND(C8/J8*2,1) -> 80530.1 | F8: =ROUND(D8/K8*2,1) -> 18349 | G8: =ROUND((C8/B8)^0.5,1) -> 55.2 | H8: =ROUND((D8/B8)^0.5,1) -> 17 | I8: =ROUND(0.00785*B8,3) -> 14.53 | J8: 140 | K8: 58 | L8: 6 | M8: 9.5 | N8: 40.9
A9: C14b | B9: 2130.9 | C9: 6094442.9 | D9: 611638.3 | E9: =ROUND(C9/J9*2,1) -> 87063.5 | F9: =ROUND(D9/K9*2,1) -> 20387.9 | G9: =ROUND((C9/B9)^0.5,1) -> 53.5 | H9: =ROUND((D9/B9)^0.5,1) -> 16.9 | I9: =ROUND(0.00785*B9,3) -> 16.728 | J9: 140 | K9: 60 | L9: 8 | M9: 9.5 | N9: 43.3
A10: C16a | B10: 2195.4 | C10: 8662194.6 | D10: 733609.4 | E10: =ROUND(C10/J10*2,1) -> 108277.4 | F10: =ROUND(D10/K10*2,1) -> 23289.2 | G10: =ROUND((C10/B10)^0.5,1) -> 62.8 | H10: =ROUND((D10/B10)^0.5,1) -> 18.3 | I10: =ROUND(0.00785*B10,3) -> 17.234 | J10: 160 | K10: 63 | L10: 6.5 | M10: 10 | N10: 45.1
A11: C16 | B11: 2515.4 | C11: 9344861.3 | D11: 833990.7 | E11: =ROUND(C11/J11*2,1) -> 116810.8 | F11: =ROUND(D11/K11*2,1) -> 25661.3 | G11: =ROUND((C11/B11)^0.5,1) -> 61 | H11: =ROUND((D11/B11)^0.5,1) -> 18.2 | I11: =ROUND(0.00785*B11,3) -> 19.746 | J11: 160 | K11: 65 | L11: 8.5 | M11: 10 | N11: 47.5
A12: C18a | B12: 2569 | C12: 12727286 | D12: 985756.2 | E12: =ROUND(C12/J12*2,1) -> 141414.3 | F12: =ROUND(D12/K12*2,1) -> 28992.8 | G12: =ROUND((C12/B12)^0.5,1) -> 70.4 | H12: =ROUND((D12/B12)^0.5,1) -> 19.6 | I12: =ROUND(0.00785*B12,3) -> 20.167 | J12: 180 | K12: 68 | L12: 7 | M12: 10.5 | N12: 49.2
A13: C18 | B13: 2929 | C13: 13699286 | D13: 1110058 | E13: =ROUND(C13/J13*2,1) -> 152214.3 | F13: =ROUND(D13/K13*2,1) -> 31715.9 | G13: =ROUND((C13/B13)^0.5,1) -> 68.4 | H13: =ROUND((D13/B13)^0.5,1) -> 19.5 | I13: =ROUND(0.00785*B13,3) -> 22.993 | J13: 180 | K13: 70 | L13: 9 | M13: 10.5 | N13: 51.6
... A32: C40c | B32: 9104.3 | C32: 197109880 | D32: 6877375.5 | E32: =ROUND(C32/J32*2,1) -> 985549.4 | F32: =ROUND(D32/K32*2,1) -> 132257.2 | G32: =ROUND((C32/B32)^0.5,1) -> 147.1 | H32: =ROUND((D32/B32)^0.5,1) -> 27.5 | I32: =ROUND(0.00785*B32,3) -> 71.469 | J32: 400 | K32: 104 | L32: 14.5 | M32: 18 | N32: 79.8

Sheet ∠
A1: 型号 | B1: A | C1: Ix | D1: Iy | E1: Wx | F1: Wy | G1: ix | H1: iy | I1: 每延米重 | J1: H | K1: B | L1: tw | M1: r1 | N1: r2
A2: ∠20x3 | B2: 113.2 | C2: 4002 | D2: 4002 | E2: =ROUND(C2/J2*2,1) -> 400.2 | F2: =ROUND(D2/K2*2,1) -> 400.2 | G2: =ROUND((C2/B2)^0.5,1) -> 5.9 | H2: =ROUND((D2/B2)^0.5,1) -> 5.9 | I2: =ROUND(B2*0.00785,3) -> 0.889 | J2: 20 | K2: 20 | L2: 3 | M2: 14 | N2: 14
A3: ∠20x4 | B3: 145.9 | C3: 4965.5 | D3: 4965.5 | E3: =ROUND(C3/J3*2,1) -> 496.6 | F3: =ROUND(D3/K3*2,1) -> 496.6 | G3: =ROUND((C3/B3)^0.5,1) -> 5.8 | H3: =ROUND((D3/B3)^0.5,1) -> 5.8 | I3: =ROUND(B3*0.00785,3) -> 1.145 | J3: 20 | K3: 20 | L3: 4 | M3: 13.6 | N3: 13.6
A4: ∠25x3 | B4: 143.2 | C4: 8167.5 | D4: 8167.5 | E4: =ROUND(C4/J4*2,1) -> 653.4 | F4: =ROUND(D4/K4*2,1) -> 653.4 | G4: =ROUND((C4/B4)^0.5,1) -> 7.6 | H4: =ROUND((D4/B4)^0.5,1) -> 7.6 | I4: =ROUND(B4*0.00785,3) -> 1.124 | J4: 25 | K4: 25 | L4: 3 | M4: 17.7 | N4: 17.7
A5: ∠25x4 | B5: 185.9 | C5: 10259.9 | D5: 10259.9 | E5: =ROUND(C5/J5*2,1) -> 820.8 | F5: =ROUND(D5/K5*2,1) -> 820.8 | G5: =ROUND((C5/B5)^0.5,1) -> 7.4 | H5: =ROUND((D5/B5)^0.5,1) -> 7.4 | I5: =ROUND(B5*0.00785,3) -> 1.459 | J5: 25 | K5: 25 | L5: 4 | M5: 17.4 | N5: 17.4
A6: ∠30x3 | B6: 174.9 | C6: 14568.8 | D6: 14568.8 | E6: =ROUND(C6/J6*2,1) -> 971.3 | F6: =ROUND(D6/K6*2,1) -> 971.3 | G6: =ROUND((C6/B6)^0.5,1) -> 9.1 | H6: =ROUND((D6/B6)^0.5,1) -> 9.1 | I6: =ROUND(B6*0.00785,3) -> 1.373 | J6: 30 | K6: 30 | L6: 3 | M6: 21.5 | N6: 21.5
A7: ∠30x4 | B7: 227.6 | C7: 18448.6 | D7: 18448.6 | E7: =ROUND(C7/J7*2,1) -> 1229.9 | F7: =ROUND(D7/K7*2,1) -> 1229.9 | G7: =ROUND((C7/B7)^0.5,1) -> 9 | H7: =ROUND((D7/B7)^0.5,1) -> 9 | I7: =ROUND(B7*0.00785,3) -> 1.787 | J7: 30 | K7: 30 | L7: 4 | M7: 21.1 | N7: 21.1
A8: ∠36x3 | B8: 210.9 | C8: 25808.2 | D8: 25808.2 | E8: =ROUND(C8/J8*2,1) -> 1433.8 | F8: =ROUND(D8/K8*2,1) -> 1433.8 | G8: =ROUND((C8/B8)^0.5,1) -> 11.1 | H8: =ROUND((D8/B8)^0.5,1) -> 11.1 | I8: =ROUND(B8*0.00785,3) -> 1.656 | J8: 36 | K8: 36 | L8: 3 | M8: 26 | N8: 26
A9: ∠36x4 | B9: 275.6 | C9: 32939.5 | D9: 32939.5 | E9: =ROUND(C9/J9*2,1) -> 1830 | F9: =ROUND(D9/K9*2,1) -> 1830 | G9: =ROUND((C9/B9)^0.5,1) -> 10.9 | H9: =ROUND((D9/B9)^0.5,1) -> 10.9 | I9: =ROUND(B9*0.00785,3) -> 2.163 | J9: 36 | K9: 36 | L9: 4 | M9: 25.6 | N9: 25.6
A10: ∠36x5 | B10: 338.2 | C10: 39483.3 | D10: 39483.3 | E10: =ROUND(C10/J10*2,1) -> 2193.5 | F10: =ROUND(D10/K10*2,1) -> 2193.5 | G10: =ROUND((C10/B10)^0.5,1) -> 10.8 | H10: =ROUND((D10/B10)^0.5,1) -> 10.8 | I10: =ROUND(B10*0.00785,3) -> 2.655 | J10: 36 | K10: 36 | L10: 5 | M10: 25.3 | N10: 25.3
A11: ∠40x3 | B11: 235.9 | C11: 35886.6 | D11: 35886.6 | E11: =ROUND(C11/J11*2,1) -> 1794.3 | F11: =ROUND(D11/K11*2,1) -> 1794.3 | G11: =ROUND((C11/B11)^0.5,1) -> 12.3 | H11: =ROUND((D11/B11)^0.5,1) -> 12.3 | I11: =ROUND(B11*0.00785,3) -> 1.852 | J11: 40 | K11: 40 | L11: 3 | M11: 29.1 | N11: 29.1
A12: ∠40x4 | B12: 308.6 | C12: 45969.8 | D12: 45969.8 | E12: =ROUND(C12/J12*2,1) -> 2298.5 | F12: =ROUND(D12/K12*2,1) -> 2298.5 | G12: =ROUND((C12/B12)^0.5,1) -> 12.2 | H12: =ROUND((D12/B12)^0.5,1) -> 12.2 | I12: =ROUND(B12*0.00785,3) -> 2.423 | J12: 40 | K12: 40 | L12: 4 | M12: 28.7 | N12: 28.7
A13: ∠40x5 | B13: 379.2 | C13: 55298.2 | D13: 55298.2 | E13: =ROUND(C13/J13*2,1) -> 2764.9 | F13: =ROUND(D13/K13*2,1) -> 2764.9 | G13: =ROUND((C13/B13)^0.5,1) -> 12.1 | H13: =ROUND((D13/B13)^0.5,1) -> 12.1 | I13: =ROUND(B13*0.00785,3) -> 2.977 | J13: 40 | K13: 40 | L13: 5 | M13: 28.3 | N13: 28.3
... A147: ∠200x125x18 | B147: 5552.6 | C147: 22383049 | D147: 6771850.7 | E147: =ROUND(C147/J147*2,1) -> 223830.5 | F147: =ROUND(D147/K147*2,1) -> 108349.6 | G147: =ROUND((C147/B147)^0.5,1) -> 63.5 | H147: =ROUND((D147/B147)^0.5,1) -> 34.9 | I147: =ROUND(B147*0.00785,3) -> 43.588 | J147: 200 | K147: 125 | L147: 18 | M147: 94.4 | N147: 132.2

Sheet 2C
A1: 型号 | B1: A | C1: Ix | D1: Iy | E1: Wx | F1: Wy | G1: ix | H1: iy | I1: 每延米重 | J1: H | K1: B | L1: tw | M1: tf1 | N1: C
A2: ="2"&'C'!A2 -> 2C5 | B2: =2*'C'!B2 -> 1385 | C2: =2*'C'!C2 -> 520287.4 | D2: =ROUND(2*('C'!D2+'C'!B2*('C'!K2-'C'!N2)^2),1) -> 419114.9 | E2: =ROUND(C2/J2*2,1) -> 20811.5 | F2: =ROUND(D2/K2*2,1) -> 22654.9 | G2: =ROUND((C2/B2)^0.5,1) -> 19.4 | H2: =ROUND((D2/B2)^0.5,1) -> 17.4 | I2: =ROUND(0.00785*B2,3) -> 10.872 | J2: ='C'!J2 -> 50 | K2: ='C'!K2 -> 37 | L2: ='C'!L2 -> 4.5 | M2: ='C'!M2 -> 7 | N2: 0
A3: ="2"&'C'!A3 -> 2C6.3 | B3: =2*'C'!B3 -> 1689.4 | C3: =2*'C'!C3 -> 1024731.6 | D3: =ROUND(2*('C'!D3+'C'!B3*('C'!K3-'C'!N3)^2),1) -> 564309.4 | E3: =ROUND(C3/J3*2,1) -> 32531.2 | F3: =ROUND(D3/K3*2,1) -> 28215.5 | G3: =ROUND((C3/B3)^0.5,1) -> 24.6 | H3: =ROUND((D3/B3)^0.5,1) -> 18.3 | I3: =ROUND(0.00785*B3,3) -> 13.262 | J3: ='C'!J3 -> 63 | K3: ='C'!K3 -> 40 | L3: ='C'!L3 -> 4.8 | M3: ='C'!M3 -> 7.5 | N3: 0
A4: ="2"&'C'!A4 -> 2C8 | B4: =2*'C'!B4 -> 2048.6 | C4: =2*'C'!C4 -> 2025960.2 | D4: =ROUND(2*('C'!D4+'C'!B4*('C'!K4-'C'!N4)^2),1) -> 745596.5 | E4: =ROUND(C4/J4*2,1) -> 50649 | F4: =ROUND(D4/K4*2,1) -> 34678.9 | G4: =ROUND((C4/B4)^0.5,1) -> 31.4 | H4: =ROUND((D4/B4)^0.5,1) -> 19.1 | I4: =ROUND(0.00785*B4,3) -> 16.082 | J4: ='C'!J4 -> 80 | K4: ='C'!K4 -> 43 | L4: ='C'!L4 -> 5 | M4: ='C'!M4 -> 8 | N4: 0
A5: ="2"&'C'!A5 -> 2C10 | B5: =2*'C'!B5 -> 2548.6 | C5: =2*'C'!C5 -> 3966096.8 | D5: =ROUND(2*('C'!D5+'C'!B5*('C'!K5-'C'!N5)^2),1) -> 1100649.9 | E5: =ROUND(C5/J5*2,1) -> 79321.9 | F5: =ROUND(D5/K5*2,1) -> 45860.4 | G5: =ROUND((C5/B5)^0.5,1) -> 39.4 | H5: =ROUND((D5/B5)^0.5,1) -> 20.8 | I5: =ROUND(0.00785*B5,3) -> 20.007 | J5: ='C'!J5 -> 100 | K5: ='C'!K5 -> 48 | L5: ='C'!L5 -> 5.3 | M5: ='C'!M5 -> 8.5 | N5: 0
A6: ="2"&'C'!A6 -> 2C12 | B6: =2*'C'!B6 -> 3071.2 | C6: =2*'C'!C6 -> 6925704.8 | D6: =ROUND(2*('C'!D6+'C'!B6*('C'!K6-'C'!N6)^2),1) -> 1554403.7 | E6: =ROUND(C6/J6*2,1) -> 115428.4 | F6: =ROUND(D6/K6*2,1) -> 58656.7 | G6: =ROUND((C6/B6)^0.5,1) -> 47.5 | H6: =ROUND((D6/B6)^0.5,1) -> 22.5 | I6: =ROUND(0.00785*B6,3) -> 24.109 | J6: ='C'!J6 -> 120 | K6: ='C'!K6 -> 53 | L6: ='C'!L6 -> 5.5 | M6: ='C'!M6 -> 9 | N6: 0
A7: ="2"&'C'!A7 -> 2C12.6 | B7: =2*'C'!B7 -> 3137.2 | C7: =2*'C'!C7 -> 7770523.2 | D7: =ROUND(2*('C'!D7+'C'!B7*('C'!K7-'C'!N7)^2),1) -> 1553372.1 | E7: =ROUND(C7/J7*2,1) -> 123341.6 | F7: =ROUND(D7/K7*2,1) -> 58617.8 | G7: =ROUND((C7/B7)^0.5,1) -> 49.8 | H7: =ROUND((D7/B7)^0.5,1) -> 22.3 | I7: =ROUND(0.00785*B7,3) -> 24.627 | J7: ='C'!J7 -> 126 | K7: ='C'!K7 -> 53 | L7: ='C'!L7 -> 5.5 | M7: ='C'!M7 -> 9 | N7: 0
A8: ="2"&'C'!A8 -> 2C14a | B8: =2*'C'!B8 -> 3701.8 | C8: =2*'C'!C8 -> 11274219 | D8: =ROUND(2*('C'!D8+'C'!B8*('C'!K8-'C'!N8)^2),1) -> 2146687.5 | E8: =ROUND(C8/J8*2,1) -> 161060.3 | F8: =ROUND(D8/K8*2,1) -> 74023.7 | G8: =ROUND((C8/B8)^0.5,1) -> 55.2 | H8: =ROUND((D8/B8)^0.5,1) -> 24.1 | I8: =ROUND(0.00785*B8,3) -> 29.059 | J8: ='C'!J8 -> 140 | K8: ='C'!K8 -> 58 | L8: ='C'!L8 -> 6 | M8: ='C'!M8 -> 9.5 | N8: 0
A9: ="2"&'C'!A9 -> 2C14b | B9: =2*'C'!B9 -> 4261.8 | C9: =2*'C'!C9 -> 12188886 | D9: =ROUND(2*('C'!D9+'C'!B9*('C'!K9-'C'!N9)^2),1) -> 2411850 | E9: =ROUND(C9/J9*2,1) -> 174126.9 | F9: =ROUND(D9/K9*2,1) -> 80395 | G9: =ROUND((C9/B9)^0.5,1) -> 53.5 | H9: =ROUND((D9/B9)^0.5,1) -> 23.8 | I9: =ROUND(0.00785*B9,3) -> 33.455 | J9: ='C'!J9 -> 140 | K9: ='C'!K9 -> 60 | L9: ='C'!L9 -> 8 | M9: ='C'!M9 -> 9.5 | N9: 0
A10: ="2"&'C'!A10 -> 2C16a | B10: =2*'C'!B10 -> 4390.8 | C10: =2*'C'!C10 -> 17324389 | D10: =ROUND(2*('C'!D10+'C'!B10*('C'!K10-'C'!N10)^2),1) -> 2874075 | E10: =ROUND(C10/J10*2,1) -> 216554.9 | F10: =ROUND(D10/K10*2,1) -> 91240.5 | G10: =ROUND((C10/B10)^0.5,1) -> 62.8 | H10: =ROUND((D10/B10)^0.5,1) -> 25.6 | I10: =ROUND(0.00785*B10,3) -> 34.468 | J10: ='C'!J10 -> 160 | K10: ='C'!K10 -> 63 | L10: ='C'!L10 -> 6.5 | M10: ='C'!M10 -> 10 | N10: 0
A11: ="2"&'C'!A11 -> 2C16 | B11: =2*'C'!B11 -> 5030.8 | C11: =2*'C'!C11 -> 18689723 | D11: =ROUND(2*('C'!D11+'C'!B11*('C'!K11-'C'!N11)^2),1) -> 3208663.9 | E11: =ROUND(C11/J11*2,1) -> 233621.5 | F11: =ROUND(D11/K11*2,1) -> 98728.1 | G11: =ROUND((C11/B11)^0.5,1) -> 61 | H11: =ROUND((D11/B11)^0.5,1) -> 25.3 | I11: =ROUND(0.00785*B11,3) -> 39.492 | J11: ='C'!J11 -> 160 | K11: ='C'!K11 -> 65 | L11: ='C'!L11 -> 8.5 | M11: ='C'!M11 -> 10 | N11: 0
A12: ="2"&'C'!A12 -> 2C18a | B12: =2*'C'!B12 -> 5138 | C12: =2*'C'!C12 -> 25454572 | D12: =ROUND(2*('C'!D12+'C'!B12*('C'!K12-'C'!N12)^2),1) -> 3787487.1 | E12: =ROUND(C12/J12*2,1) -> 282828.6 | F12: =ROUND(D12/K12*2,1) -> 111396.7 | G12: =ROUND((C12/B12)^0.5,1) -> 70.4 | H12: =ROUND((D12/B12)^0.5,1) -> 27.2 | I12: =ROUND(0.00785*B12,3) -> 40.333 | J12: ='C'!J12 -> 180 | K12: ='C'!K12 -> 68 | L12: ='C'!L12 -> 7 | M12: ='C'!M12 -> 10.5 | N12: 0
A13: ="2"&'C'!A13 -> 2C18 | B13: =2*'C'!B13 -> 5858 | C13: =2*'C'!C13 -> 27398572 | D13: =ROUND(2*('C'!D13+'C'!B13*('C'!K13-'C'!N13)^2),1) -> 4203400.5 | E13: =ROUND(C13/J13*2,1) -> 304428.6 | F13: =ROUND(D13/K13*2,1) -> 120097.2 | G13: =ROUND((C13/B13)^0.5,1) -> 68.4 | H13: =ROUND((D13/B13)^0.5,1) -> 26.8 | I13: =ROUND(0.00785*B13,3) -> 45.985 | J13: ='C'!J13 -> 180 | K13: ='C'!K13 -> 70 | L13: ='C'!L13 -> 9 | M13: ='C'!M13 -> 10.5 | N13: 0
... A32: ="2"&'C'!A32 -> 2C40c | B32: =2*'C'!B32 -> 18208.6 | C32: =2*'C'!C32 -> 394219760 | D32: =ROUND(2*('C'!D32+'C'!B32*('C'!K32-'C'!N32)^2),1) -> 24418436 | E32: =ROUND(C32/J32*2,1) -> 1971098.8 | F32: =ROUND(D32/K32*2,1) -> 469585.3 | G32: =ROUND((C32/B32)^0.5,1) -> 147.1 | H32: =ROUND((D32/B32)^0.5,1) -> 36.6 | I32: =ROUND(0.00785*B32,3) -> 142.938 | J32: ='C'!J32 -> 400 | K32: ='C'!K32 -> 104 | L32: ='C'!L32 -> 14.5 | M32: ='C'!M32 -> 18 | N32: 0

Sheet O
A1: 型号 | B1: A | C1: I | D1: W | E1: i | F1: 每延米重 | G1: D | H1: d
A2: 377X6 | B2: =ROUND(((PI()*(G2^2-(G2-2*H2)^2))/4),1) -> 6993.2 | C2: =ROUND((PI()*(G2^4-(G2-2*H2)^4))/64,1) -> 1.203501e+08 | D2: =ROUND((PI()*(G2^3-(G2-2*H2)^4/G2))/32,1) -> 638462 | E2: =ROUND((C2/B2)^0.5,1) -> 131.2 | F2: =ROUND(((PI()*(G2^2-(G2-2*H2)^2))/4*0.00785),3) -> 54.897 | G2: 377 | H2: 6
A3: 426X6 | B3: =ROUND(((PI()*(G3^2-(G3-2*H3)^2))/4),1) -> 7916.8 | C3: =ROUND((PI()*(G3^4-(G3-2*H3)^4))/64,1) -> 1.7460136e+08 | D3: =ROUND((PI()*(G3^3-(G3-2*H3)^4/G3))/32,1) -> 819724.7 | E3: =ROUND((C3/B3)^0.5,1) -> 148.5 | F3: =ROUND(((PI()*(G3^2-(G3-2*H3)^2))/4*0.00785),3) -> 62.147 | G3: 426 | H3: 6
A4: 600X8 | B4: =ROUND(((PI()*(G4^2-(G4-2*H4)^2))/4),1) -> 14878.6 | C4: =ROUND((PI()*(G4^4-(G4-2*H4)^4))/64,1) -> 6.5191998e+08 | D4: =ROUND((PI()*(G4^3-(G4-2*H4)^4/G4))/32,1) -> 2173066.6 | E4: =ROUND((C4/B4)^0.5,1) -> 209.3 | F4: =ROUND(((PI()*(G4^2-(G4-2*H4)^2))/4*0.00785),3) -> 116.797 | G4: 600 | H4: 8
A5: 630X6 | B5: =ROUND(((PI()*(G5^2-(G5-2*H5)^2))/4),1) -> 11762.1 | C5: =ROUND((PI()*(G5^4-(G5-2*H5)^4))/64,1) -> 5.7253898e+08 | D5: =ROUND((PI()*(G5^3-(G5-2*H5)^4/G5))/32,1) -> 1817584 | E5: =ROUND((C5/B5)^0.5,1) -> 220.6 | F5: =ROUND(((PI()*(G5^2-(G5-2*H5)^2))/4*0.00785),3) -> 92.333 | G5: 630 | H5: 6
